<?xml version='1.0' encoding='utf-8'?>
<mujoco model="Nero Fourier excitation scene">
  <compiler angle="radian" autolimits="true" />
  <option gravity="0 0 -9.81" integrator="implicitfast" />
  <statistic center="0 0 0.4" extent="0.8" />
  <visual>
    <headlight diffuse="0.6 0.6 0.6" ambient="0.3 0.3 0.3" specular="0 0 0" />
    <rgba haze="0.15 0.25 0.35 1" />
    <global azimuth="-140" elevation="-30" />
  </visual>
  <asset>
    <texture type="skybox" builtin="flat" rgb1="0 0 0" rgb2="0 0 0" width="512" height="3072" />
    <texture type="2d" name="groundplane" builtin="checker" mark="edge" rgb1="0.2 0.3 0.4" rgb2="0.1 0.2 0.3" markrgb="0.8 0.8 0.8" width="300" height="300" />
    <material name="groundplane" texture="groundplane" texuniform="true" texrepeat="5 5" reflectance="0.2" />
    <mesh name="base_link" content_type="model/stl" file="/mnt/code/lcx/Nero_collection/urdf/nero/meshes/base_link.stl" />
    <mesh name="link1" content_type="model/stl" file="/mnt/code/lcx/Nero_collection/urdf/nero/meshes/link1.stl" />
    <mesh name="link2" content_type="model/stl" file="/mnt/code/lcx/Nero_collection/urdf/nero/meshes/link2.stl" />
    <mesh name="link3" content_type="model/stl" file="/mnt/code/lcx/Nero_collection/urdf/nero/meshes/link3.stl" />
    <mesh name="link4" content_type="model/stl" file="/mnt/code/lcx/Nero_collection/urdf/nero/meshes/link4.stl" />
    <mesh name="link5" content_type="model/stl" file="/mnt/code/lcx/Nero_collection/urdf/nero/meshes/link5.stl" />
    <mesh name="link6" content_type="model/stl" file="/mnt/code/lcx/Nero_collection/urdf/nero/meshes/link6.stl" />
    <mesh name="link7" content_type="model/stl" file="/mnt/code/lcx/Nero_collection/urdf/nero/meshes/link7.stl" />
    <mesh name="gripper_flange" content_type="model/stl" file="/mnt/code/lcx/Nero_collection/urdf/nero/meshes/gripper_flange.stl" />
    <mesh name="gripper_base" content_type="model/stl" file="/mnt/code/lcx/Nero_collection/urdf/nero/meshes/gripper_base.stl" />
    <mesh name="gripper_link1" content_type="model/stl" file="/mnt/code/lcx/Nero_collection/urdf/nero/meshes/gripper_link1.stl" />
    <mesh name="gripper_link2" content_type="model/stl" file="/mnt/code/lcx/Nero_collection/urdf/nero/meshes/gripper_link2.stl" />
  </asset>
  <worldbody>
    <light pos="0 0 1.5" dir="0 0 -1" directional="true" />
    <geom name="world_floor" size="0 0 0.05" type="plane" material="groundplane" pos="0 0 -0.02" />
    <body name="base_link">
      <inertial pos="-0.00319466 -5.46761e-05 0.0432176" quat="0.712681 0.00763931 0.0100067 0.701375" mass="1.06458" diaginertia="0.00114403 0.00102664 0.000908653" />
      <geom type="mesh" mesh="base_link" name="base_link_collision_0" />
      <body name="link1" pos="0 0 0.138">
        <inertial pos="-0.000768106 -5.71803e-05 -0.00686373" quat="0.998496 0.0243284 -0.0474034 0.0129308" mass="0.767105" diaginertia="0.000668361 0.000545022 0.000513619" />
        <joint name="joint1" pos="0 0 0" axis="0 0 1" range="-2.70526 2.70526" actuatorfrcrange="-100 100" />
        <geom type="mesh" mesh="link1" name="link1_collision_0" />
        <body name="link2" quat="1.89469e-08 1.89469e-08 0.707107 -0.707107">
          <inertial pos="0.000796867 -0.0789033 0.00111849" quat="0.724173 0.689546 -0.00281155 -0.00963045" mass="0.693819" diaginertia="0.00201137 0.00182229 0.000632162" />
          <joint name="joint2" pos="0 0 0" axis="0 0 1" range="-1.74 1.74" actuatorfrcrange="-100 100" />
          <geom type="mesh" mesh="link2" name="link2_collision_0" />
          <body name="link3" pos="0 -0.31 0" quat="-1.37922e-08 1.37922e-08 -0.707107 0.707107">
            <inertial pos="0.000145134 -0.00121379 -0.0486114" quat="0.999978 -0.00572699 -0.000503892 -0.00336231" mass="0.672465" diaginertia="0.0034323 0.00338703 0.000288126" />
            <joint name="joint3" pos="0 0 0" axis="0 0 1" range="-2.75 2.75" actuatorfrcrange="-100 100" />
            <geom type="mesh" mesh="link3" name="link3_collision_0" />
            <body name="link4" quat="-1.37922e-08 1.37922e-08 -0.707107 0.707107">
              <inertial pos="-0.000313346 -0.0567519 0.000760561" quat="0.743967 0.668141 -0.00555621 -0.00837616" mass="0.484514" diaginertia="0.000503972 0.000403451 0.00023296" />
              <joint name="joint4" pos="0 0 0" axis="0 0 1" range="-1.01 2.14" actuatorfrcrange="-100 100" />
              <geom type="mesh" mesh="link4" name="link4_collision_0" />
              <body name="link5" pos="0 -0.27001 0" quat="0.5 0.5 -0.5 0.5">
                <inertial pos="0.00265591 0.00201196 -0.116209" quat="0.994383 -0.0299767 0.0135244 0.100607" mass="0.583684" diaginertia="0.000897188 0.000859677 0.000214923" />
                <joint name="joint5" pos="0 0 0" axis="0 0 1" range="-2.75 2.75" actuatorfrcrange="-100 100" />
                <geom type="mesh" mesh="link5" name="link5_collision_0" />
                <body name="link6" quat="0.5 0.5 -0.5 0.5">
                  <inertial pos="9.50151e-05 0.00107831 -0.00019111" quat="0.708463 0.705104 -0.0268147 0.0137484" mass="0.314041" diaginertia="6.02857e-05 5.75589e-05 4.69904e-05" />
                  <joint name="joint6" pos="0 0 0" axis="0 0 1" range="-0.73 0.95" actuatorfrcrange="-100 100" />
                  <geom type="mesh" mesh="link6" name="link6_collision_0" />
                  <body name="link7" pos="0 -0.0235 0" quat="0.707107 0.707107 0 0">
                    <inertial pos="-0.00014 -0.0001 -0.00275" quat="0.5 0.5 -0.5 0.5" mass="1e-06" diaginertia="2e-07 1.1e-07 1.1e-07" />
                    <joint name="joint7" pos="0 0 0" axis="0 0 1" range="-1.5708 1.5708" actuatorfrcrange="-100 100" />
                    <geom type="mesh" mesh="link7" name="link7_collision_0" />
                    <body name="gripper_flange" pos="0.031 0 -0.0235" quat="0.499998 -0.5 0.500002 -0.5">
                      <inertial pos="0.000253201 -0.000322696 -0.0100829" quat="0.707107 0.707107 0 0" mass="0.047711" diaginertia="3.61411e-05 2.69594e-05 1.78242e-05" />
                      <geom type="mesh" mesh="gripper_flange" name="gripper_flange_collision_0" />
                      <body name="gripper_base" pos="0 0 0.006">
                        <inertial pos="-0.000183807 8.05033e-05 0.0321437" quat="0.999976 9.08444e-05 0.00689649 0.000788512" mass="0.45" diaginertia="0.000929442 0.000714469 0.000394318" />
                        <geom type="mesh" mesh="gripper_base" name="gripper_base_collision_0" />
                        <body name="gripper_link" />
                        <body name="gripper_link1" pos="0 0 0.138" quat="1.89469e-08 1.89469e-08 0.707107 0.707107">
                          <inertial pos="0.000651232 -0.049193 0.00972259" quat="0.477798 0.572974 -0.518028 0.418398" mass="0.025" diaginertia="7.74531e-05 7.36783e-05 5.0886e-06" />
                          <geom type="mesh" mesh="gripper_link1" name="gripper_link1_collision_0" />
                        </body>
                        <body name="gripper_link2" pos="0 0 0.138" quat="0.707107 0.707107 0 0">
                          <inertial pos="0.000651232 -0.049193 0.00972259" quat="0.477798 0.572974 -0.518028 0.418398" mass="0.025" diaginertia="7.74531e-05 7.36783e-05 5.0886e-06" />
                          <geom type="mesh" mesh="gripper_link2" name="gripper_link2_collision_0" />
                        </body>
                      </body>
                    </body>
                  </body>
                </body>
              </body>
            </body>
          </body>
        </body>
      </body>
    </body>
    <geom name="world_ee_path_0" type="sphere" pos="-0.163815481239 -0.111831141636 0.51611345475" size="0.006" rgba="1 0.58 0.05 0.9" contype="0" conaffinity="0" group="4" />
    <geom name="world_ee_path_1" type="sphere" pos="-0.169670609823 -0.109433200579 0.51089725417" size="0.006" rgba="1 0.58 0.05 0.9" contype="0" conaffinity="0" group="4" />
    <geom name="world_ee_path_2" type="sphere" pos="-0.177108154106 -0.10882316494 0.503231550895" size="0.006" rgba="1 0.58 0.05 0.9" contype="0" conaffinity="0" group="4" />
    <geom name="world_ee_path_3" type="sphere" pos="-0.185107401432 -0.110095560096 0.493722473482" size="0.006" rgba="1 0.58 0.05 0.9" contype="0" conaffinity="0" group="4" />
    <geom name="world_ee_path_4" type="sphere" pos="-0.192498204698 -0.113254071604 0.483320749062" size="0.006" rgba="1 0.58 0.05 0.9" contype="0" conaffinity="0" group="4" />
    <geom name="world_ee_path_5" type="sphere" pos="-0.198195438569 -0.118164254319 0.473236044641" size="0.006" rgba="1 0.58 0.05 0.9" contype="0" conaffinity="0" group="4" />
    <geom name="world_ee_path_6" type="sphere" pos="-0.201389489536 -0.124501772961 0.464774612354" size="0.006" rgba="1 0.58 0.05 0.9" contype="0" conaffinity="0" group="4" />
    <geom name="world_ee_path_7" type="sphere" pos="-0.201645135561 -0.131728345881 0.459132822024" size="0.006" rgba="1 0.58 0.05 0.9" contype="0" conaffinity="0" group="4" />
    <geom name="world_ee_path_8" type="sphere" pos="-0.198905075762 -0.139116087816 0.457198970854" size="0.006" rgba="1 0.58 0.05 0.9" contype="0" conaffinity="0" group="4" />
    <geom name="world_ee_path_9" type="sphere" pos="-0.193431495455 -0.145822537698 0.459408366408" size="0.006" rgba="1 0.58 0.05 0.9" contype="0" conaffinity="0" group="4" />
    <geom name="world_ee_path_10" type="sphere" pos="-0.185730013237 -0.151004845222 0.465675030614" size="0.006" rgba="1 0.58 0.05 0.9" contype="0" conaffinity="0" group="4" />
    <geom name="world_ee_path_11" type="sphere" pos="-0.176485849267 -0.153952102193 0.475405946495" size="0.006" rgba="1 0.58 0.05 0.9" contype="0" conaffinity="0" group="4" />
    <geom name="world_ee_path_12" type="sphere" pos="-0.166517483745 -0.154204724325 0.487594983059" size="0.006" rgba="1 0.58 0.05 0.9" contype="0" conaffinity="0" group="4" />
    <geom name="world_ee_path_13" type="sphere" pos="-0.156733757135 -0.151622770559 0.500983744148" size="0.006" rgba="1 0.58 0.05 0.9" contype="0" conaffinity="0" group="4" />
    <geom name="world_ee_path_14" type="sphere" pos="-0.148073061128 -0.146374255188 0.514258529109" size="0.006" rgba="1 0.58 0.05 0.9" contype="0" conaffinity="0" group="4" />
    <geom name="world_ee_path_15" type="sphere" pos="-0.141408706222 -0.138847325047 0.526235179975" size="0.006" rgba="1 0.58 0.05 0.9" contype="0" conaffinity="0" group="4" />
    <geom name="world_ee_path_16" type="sphere" pos="-0.137421906946 -0.129532691665 0.535985309635" size="0.006" rgba="1 0.58 0.05 0.9" contype="0" conaffinity="0" group="4" />
    <geom name="world_ee_path_17" type="sphere" pos="-0.136468489545 -0.118943390803 0.542885957805" size="0.006" rgba="1 0.58 0.05 0.9" contype="0" conaffinity="0" group="4" />
    <geom name="world_ee_path_18" type="sphere" pos="-0.138484552604 -0.107614646938 0.546614238346" size="0.006" rgba="1 0.58 0.05 0.9" contype="0" conaffinity="0" group="4" />
    <geom name="world_ee_path_19" type="sphere" pos="-0.142973871353 -0.0961676364874 0.547130229901" size="0.006" rgba="1 0.58 0.05 0.9" contype="0" conaffinity="0" group="4" />
    <geom name="world_ee_path_20" type="sphere" pos="-0.149091166535 -0.0853681293582 0.544678493023" size="0.006" rgba="1 0.58 0.05 0.9" contype="0" conaffinity="0" group="4" />
    <geom name="world_ee_path_21" type="sphere" pos="-0.155795650293 -0.076104541654 0.539801681916" size="0.006" rgba="1 0.58 0.05 0.9" contype="0" conaffinity="0" group="4" />
    <geom name="world_ee_path_22" type="sphere" pos="-0.162023923734 -0.069257026057 0.533328427229" size="0.006" rgba="1 0.58 0.05 0.9" contype="0" conaffinity="0" group="4" />
    <geom name="world_ee_path_23" type="sphere" pos="-0.166835470941 -0.0654980518512 0.526297240787" size="0.006" rgba="1 0.58 0.05 0.9" contype="0" conaffinity="0" group="4" />
    <geom name="world_ee_path_24" type="sphere" pos="-0.169510626408 -0.0651094480801 0.519809650844" size="0.006" rgba="1 0.58 0.05 0.9" contype="0" conaffinity="0" group="4" />
    <geom name="world_ee_path_25" type="sphere" pos="-0.169608326679 -0.0678953656235 0.514845939902" size="0.006" rgba="1 0.58 0.05 0.9" contype="0" conaffinity="0" group="4" />
    <geom name="world_ee_path_26" type="sphere" pos="-0.167001384617 -0.0732250947992 0.512098301077" size="0.006" rgba="1 0.58 0.05 0.9" contype="0" conaffinity="0" group="4" />
    <geom name="world_ee_path_27" type="sphere" pos="-0.161898375729 -0.0801855636707 0.511868716282" size="0.006" rgba="1 0.58 0.05 0.9" contype="0" conaffinity="0" group="4" />
    <geom name="world_ee_path_28" type="sphere" pos="-0.154844744075 -0.0877869143884 0.514052656801" size="0.006" rgba="1 0.58 0.05 0.9" contype="0" conaffinity="0" group="4" />
    <geom name="world_ee_path_29" type="sphere" pos="-0.146685384982 -0.0951541881755 0.51820163595" size="0.006" rgba="1 0.58 0.05 0.9" contype="0" conaffinity="0" group="4" />
    <geom name="world_ee_path_30" type="sphere" pos="-0.13847413682 -0.101650591641 0.523637918868" size="0.006" rgba="1 0.58 0.05 0.9" contype="0" conaffinity="0" group="4" />
    <geom name="world_ee_path_31" type="sphere" pos="-0.131330191539 -0.106907482012 0.529586030285" size="0.006" rgba="1 0.58 0.05 0.9" contype="0" conaffinity="0" group="4" />
    <geom name="world_ee_path_32" type="sphere" pos="-0.126259551917 -0.110774853937 0.535288646033" size="0.006" rgba="1 0.58 0.05 0.9" contype="0" conaffinity="0" group="4" />
    <geom name="world_ee_path_33" type="sphere" pos="-0.123974249375 -0.113238606279 0.540088343605" size="0.006" rgba="1 0.58 0.05 0.9" contype="0" conaffinity="0" group="4" />
    <geom name="world_ee_path_34" type="sphere" pos="-0.124749665547 -0.114359445145 0.543475925279" size="0.006" rgba="1 0.58 0.05 0.9" contype="0" conaffinity="0" group="4" />
    <geom name="world_ee_path_35" type="sphere" pos="-0.128358577858 -0.114265624789 0.545119835566" size="0.006" rgba="1 0.58 0.05 0.9" contype="0" conaffinity="0" group="4" />
    <geom name="world_ee_path_36" type="sphere" pos="-0.134106130205 -0.1131902015 0.544890710968" size="0.006" rgba="1 0.58 0.05 0.9" contype="0" conaffinity="0" group="4" />
    <geom name="world_ee_path_37" type="sphere" pos="-0.140962695665 -0.111509490275 0.542881552763" size="0.006" rgba="1 0.58 0.05 0.9" contype="0" conaffinity="0" group="4" />
    <geom name="world_ee_path_38" type="sphere" pos="-0.147760477004 -0.10973539368 0.539408943655" size="0.006" rgba="1 0.58 0.05 0.9" contype="0" conaffinity="0" group="4" />
    <geom name="world_ee_path_39" type="sphere" pos="-0.153400477658 -0.10844215218 0.534977038218" size="0.006" rgba="1 0.58 0.05 0.9" contype="0" conaffinity="0" group="4" />
    <geom name="world_ee_path_40" type="sphere" pos="-0.157020443796 -0.108148145034 0.530197751749" size="0.006" rgba="1 0.58 0.05 0.9" contype="0" conaffinity="0" group="4" />
    <geom name="world_ee_path_41" type="sphere" pos="-0.158098323621 -0.109199762647 0.525680090189" size="0.006" rgba="1 0.58 0.05 0.9" contype="0" conaffinity="0" group="4" />
    <geom name="world_ee_path_42" type="sphere" pos="-0.15649389481 -0.111703534366 0.52191646041" size="0.006" rgba="1 0.58 0.05 0.9" contype="0" conaffinity="0" group="4" />
    <geom name="world_ee_path_43" type="sphere" pos="-0.152446995364 -0.115529520214 0.519196301625" size="0.006" rgba="1 0.58 0.05 0.9" contype="0" conaffinity="0" group="4" />
    <geom name="world_ee_path_44" type="sphere" pos="-0.146548312461 -0.120378361139 0.51756828737" size="0.006" rgba="1 0.58 0.05 0.9" contype="0" conaffinity="0" group="4" />
    <geom name="world_ee_path_45" type="sphere" pos="-0.139684846454 -0.125879936249 0.516857245262" size="0.006" rgba="1 0.58 0.05 0.9" contype="0" conaffinity="0" group="4" />
    <geom name="world_ee_path_46" type="sphere" pos="-0.132950391363 -0.131681630612 0.516725953226" size="0.006" rgba="1 0.58 0.05 0.9" contype="0" conaffinity="0" group="4" />
    <geom name="world_ee_path_47" type="sphere" pos="-0.127511996639 -0.137492973881 0.516759314396" size="0.006" rgba="1 0.58 0.05 0.9" contype="0" conaffinity="0" group="4" />
    <geom name="world_ee_path_48" type="sphere" pos="-0.124437221115 -0.143079206687 0.516544400941" size="0.006" rgba="1 0.58 0.05 0.9" contype="0" conaffinity="0" group="4" />
    <geom name="world_ee_path_49" type="sphere" pos="-0.124506336544 -0.148227446739 0.515728505552" size="0.006" rgba="1 0.58 0.05 0.9" contype="0" conaffinity="0" group="4" />
    <geom name="world_ee_path_50" type="sphere" pos="-0.128048765764 -0.152726464125 0.514055090156" size="0.006" rgba="1 0.58 0.05 0.9" contype="0" conaffinity="0" group="4" />
    <geom name="world_ee_path_51" type="sphere" pos="-0.134847348892 -0.156390994844 0.511392129056" size="0.006" rgba="1 0.58 0.05 0.9" contype="0" conaffinity="0" group="4" />
    <geom name="world_ee_path_52" type="sphere" pos="-0.14414412297 -0.159128198227 0.50776667244" size="0.006" rgba="1 0.58 0.05 0.9" contype="0" conaffinity="0" group="4" />
    <geom name="world_ee_path_53" type="sphere" pos="-0.154756538276 -0.161008680111 0.503402688916" size="0.006" rgba="1 0.58 0.05 0.9" contype="0" conaffinity="0" group="4" />
    <geom name="world_ee_path_54" type="sphere" pos="-0.16527899762 -0.162291878849 0.498739178897" size="0.006" rgba="1 0.58 0.05 0.9" contype="0" conaffinity="0" group="4" />
    <geom name="world_ee_path_55" type="sphere" pos="-0.1743157942 -0.163375641084 0.494399156947" size="0.006" rgba="1 0.58 0.05 0.9" contype="0" conaffinity="0" group="4" />
    <geom name="world_ee_path_56" type="sphere" pos="-0.180684921987 -0.164680422786 0.491095076031" size="0.006" rgba="1 0.58 0.05 0.9" contype="0" conaffinity="0" group="4" />
    <geom name="world_ee_path_57" type="sphere" pos="-0.183553461984 -0.166514108175 0.489484721246" size="0.006" rgba="1 0.58 0.05 0.9" contype="0" conaffinity="0" group="4" />
    <geom name="world_ee_path_58" type="sphere" pos="-0.182501056052 -0.168973791986 0.49001634205" size="0.006" rgba="1 0.58 0.05 0.9" contype="0" conaffinity="0" group="4" />
    <geom name="world_ee_path_59" type="sphere" pos="-0.177534960293 -0.171924032148 0.492809563257" size="0.006" rgba="1 0.58 0.05 0.9" contype="0" conaffinity="0" group="4" />
    <geom name="world_ee_path_60" type="sphere" pos="-0.169082734882 -0.17505922865 0.497608121311" size="0.006" rgba="1 0.58 0.05 0.9" contype="0" conaffinity="0" group="4" />
    <geom name="world_ee_path_61" type="sphere" pos="-0.1579700137 -0.178024855417 0.503819043614" size="0.006" rgba="1 0.58 0.05 0.9" contype="0" conaffinity="0" group="4" />
    <geom name="world_ee_path_62" type="sphere" pos="-0.14536878983 -0.180548188636 0.51062822062" size="0.006" rgba="1 0.58 0.05 0.9" contype="0" conaffinity="0" group="4" />
    <geom name="world_ee_path_63" type="sphere" pos="-0.132694300828 -0.182522550226 0.517159677745" size="0.006" rgba="1 0.58 0.05 0.9" contype="0" conaffinity="0" group="4" />
    <geom name="world_ee_path_64" type="sphere" pos="-0.121441553174 -0.18400712052 0.522631711892" size="0.006" rgba="1 0.58 0.05 0.9" contype="0" conaffinity="0" group="4" />
    <geom name="world_ee_path_65" type="sphere" pos="-0.11297698451 -0.185144403106 0.526466044922" size="0.006" rgba="1 0.58 0.05 0.9" contype="0" conaffinity="0" group="4" />
    <geom name="world_ee_path_66" type="sphere" pos="-0.108322423905 -0.186040586969 0.528329514795" size="0.006" rgba="1 0.58 0.05 0.9" contype="0" conaffinity="0" group="4" />
    <geom name="world_ee_path_67" type="sphere" pos="-0.107978475687 -0.186674042665 0.528121118087" size="0.006" rgba="1 0.58 0.05 0.9" contype="0" conaffinity="0" group="4" />
    <geom name="world_ee_path_68" type="sphere" pos="-0.111831715502 -0.186879893703 0.525939768867" size="0.006" rgba="1 0.58 0.05 0.9" contype="0" conaffinity="0" group="4" />
    <geom name="world_ee_path_69" type="sphere" pos="-0.119175813801 -0.186414089297 0.522064628988" size="0.006" rgba="1 0.58 0.05 0.9" contype="0" conaffinity="0" group="4" />
    <geom name="world_ee_path_70" type="sphere" pos="-0.1288507074 -0.185056249142 0.516953644785" size="0.006" rgba="1 0.58 0.05 0.9" contype="0" conaffinity="0" group="4" />
    <geom name="world_ee_path_71" type="sphere" pos="-0.139469628457 -0.182693118493 0.51123723965" size="0.006" rgba="1 0.58 0.05 0.9" contype="0" conaffinity="0" group="4" />
    <geom name="world_ee_path_72" type="sphere" pos="-0.149674111549 -0.179342128706 0.505674593439" size="0.006" rgba="1 0.58 0.05 0.9" contype="0" conaffinity="0" group="4" />
    <geom name="world_ee_path_73" type="sphere" pos="-0.158349534866 -0.175113231052 0.501056292241" size="0.006" rgba="1 0.58 0.05 0.9" contype="0" conaffinity="0" group="4" />
    <geom name="world_ee_path_74" type="sphere" pos="-0.164755500377 -0.170141210068 0.49806714292" size="0.006" rgba="1 0.58 0.05 0.9" contype="0" conaffinity="0" group="4" />
    <geom name="world_ee_path_75" type="sphere" pos="-0.168564263107 -0.164531316096 0.497146519996" size="0.006" rgba="1 0.58 0.05 0.9" contype="0" conaffinity="0" group="4" />
    <geom name="world_ee_path_76" type="sphere" pos="-0.16983318738 -0.158347259894 0.498388271524" size="0.006" rgba="1 0.58 0.05 0.9" contype="0" conaffinity="0" group="4" />
    <geom name="world_ee_path_77" type="sphere" pos="-0.168947152605 -0.151644699416 0.501509297302" size="0.006" rgba="1 0.58 0.05 0.9" contype="0" conaffinity="0" group="4" />
    <geom name="world_ee_path_78" type="sphere" pos="-0.166554215137 -0.144529478709 0.505894635023" size="0.006" rgba="1 0.58 0.05 0.9" contype="0" conaffinity="0" group="4" />
    <geom name="world_ee_path_79" type="sphere" pos="-0.163496011385 -0.137207559196 0.510705608235" size="0.006" rgba="1 0.58 0.05 0.9" contype="0" conaffinity="0" group="4" />
    <geom name="world_ee_path_80" type="sphere" pos="-0.160718857445 -0.129997489908 0.515021422015" size="0.006" rgba="1 0.58 0.05 0.9" contype="0" conaffinity="0" group="4" />
    <geom name="world_ee_path_81" type="sphere" pos="-0.159151485596 -0.123295697353 0.517978205754" size="0.006" rgba="1 0.58 0.05 0.9" contype="0" conaffinity="0" group="4" />
    <geom name="world_ee_path_82" type="sphere" pos="-0.159551111896 -0.117510944195 0.518877301958" size="0.006" rgba="1 0.58 0.05 0.9" contype="0" conaffinity="0" group="4" />
    <geom name="world_ee_path_83" type="sphere" pos="-0.162343395155 -0.113001154615 0.517255070746" size="0.006" rgba="1 0.58 0.05 0.9" contype="0" conaffinity="0" group="4" />
  </worldbody>
</mujoco>