<?xml version='1.0' encoding='utf-8'?>
<mujoco model="Nero Fourier excitation scene">
  <compiler angle="radian" autolimits="true" />
  <option gravity="0 0 -9.81" integrator="implicitfast" />
  <statistic center="0 0 0.4" extent="0.8" />
  <visual>
    <headlight diffuse="0.6 0.6 0.6" ambient="0.3 0.3 0.3" specular="0 0 0" />
    <rgba haze="0.15 0.25 0.35 1" />
    <global azimuth="-140" elevation="-30" />
  </visual>
  <asset>
    <texture type="skybox" builtin="flat" rgb1="0 0 0" rgb2="0 0 0" width="512" height="3072" />
    <texture type="2d" name="groundplane" builtin="checker" mark="edge" rgb1="0.2 0.3 0.4" rgb2="0.1 0.2 0.3" markrgb="0.8 0.8 0.8" width="300" height="300" />
    <material name="groundplane" texture="groundplane" texuniform="true" texrepeat="5 5" reflectance="0.2" />
    <mesh name="base_link" file="/mnt/code/lcx/Nero_collection/urdf/nero/meshes/base_link.stl" />
    <mesh name="link1" file="/mnt/code/lcx/Nero_collection/urdf/nero/meshes/link1.stl" />
    <mesh name="link2" file="/mnt/code/lcx/Nero_collection/urdf/nero/meshes/link2.stl" />
    <mesh name="link3" file="/mnt/code/lcx/Nero_collection/urdf/nero/meshes/link3.stl" />
    <mesh name="link4" file="/mnt/code/lcx/Nero_collection/urdf/nero/meshes/link4.stl" />
    <mesh name="link5" file="/mnt/code/lcx/Nero_collection/urdf/nero/meshes/link5.stl" />
    <mesh name="link6" file="/mnt/code/lcx/Nero_collection/urdf/nero/meshes/link6.stl" />
    <mesh name="link7" file="/mnt/code/lcx/Nero_collection/urdf/nero/meshes/link7.stl" />
    <mesh name="gripper_flange" file="/mnt/code/lcx/Nero_collection/urdf/nero/meshes/gripper_flange.stl" />
    <mesh name="gripper_base" file="/mnt/code/lcx/Nero_collection/urdf/nero/meshes/gripper_base.stl" />
    <mesh name="gripper_link1" file="/mnt/code/lcx/Nero_collection/urdf/nero/meshes/gripper_link1.stl" />
    <mesh name="gripper_link2" file="/mnt/code/lcx/Nero_collection/urdf/nero/meshes/gripper_link2.stl" />
  </asset>
  <worldbody>
    <light pos="0 0 1.5" dir="0 0 -1" directional="true" />
    <geom name="world_floor" size="0 0 0.05" type="plane" material="groundplane" pos="0 0 -0.02" />
    <body name="base_link">
      <inertial pos="-0.00319466 -5.46761e-05 0.0432176" quat="0.712681 0.00763931 0.0100067 0.701375" mass="1.06458" diaginertia="0.00114403 0.00102664 0.000908653" />
      <geom type="mesh" mesh="base_link" name="base_link_collision_0" />
      <body name="link1" pos="0 0 0.138">
        <inertial pos="-0.000768106 -5.71803e-05 -0.00686373" quat="0.998496 0.0243284 -0.0474034 0.0129308" mass="0.767105" diaginertia="0.000668361 0.000545022 0.000513619" />
        <joint name="joint1" pos="0 0 0" axis="0 0 1" range="-2.70526 2.70526" actuatorfrcrange="-100 100" />
        <geom type="mesh" mesh="link1" name="link1_collision_0" />
        <body name="link2" quat="1.89469e-08 1.89469e-08 0.707107 -0.707107">
          <inertial pos="0.000796867 -0.0789033 0.00111849" quat="0.724173 0.689546 -0.00281155 -0.00963045" mass="0.693819" diaginertia="0.00201137 0.00182229 0.000632162" />
          <joint name="joint2" pos="0 0 0" axis="0 0 1" range="-1.74 1.74" actuatorfrcrange="-100 100" />
          <geom type="mesh" mesh="link2" name="link2_collision_0" />
          <body name="link3" pos="0 -0.31 0" quat="-1.37922e-08 1.37922e-08 -0.707107 0.707107">
            <inertial pos="0.000145134 -0.00121379 -0.0486114" quat="0.999978 -0.00572699 -0.000503892 -0.00336231" mass="0.672465" diaginertia="0.0034323 0.00338703 0.000288126" />
            <joint name="joint3" pos="0 0 0" axis="0 0 1" range="-2.75 2.75" actuatorfrcrange="-100 100" />
            <geom type="mesh" mesh="link3" name="link3_collision_0" />
            <body name="link4" quat="-1.37922e-08 1.37922e-08 -0.707107 0.707107">
              <inertial pos="-0.000313346 -0.0567519 0.000760561" quat="0.743967 0.668141 -0.00555621 -0.00837616" mass="0.484514" diaginertia="0.000503972 0.000403451 0.00023296" />
              <joint name="joint4" pos="0 0 0" axis="0 0 1" range="-1.01 2.14" actuatorfrcrange="-100 100" />
              <geom type="mesh" mesh="link4" name="link4_collision_0" />
              <body name="link5" pos="0 -0.27001 0" quat="0.5 0.5 -0.5 0.5">
                <inertial pos="0.00265591 0.00201196 -0.116209" quat="0.994383 -0.0299767 0.0135244 0.100607" mass="0.583684" diaginertia="0.000897188 0.000859677 0.000214923" />
                <joint name="joint5" pos="0 0 0" axis="0 0 1" range="-2.75 2.75" actuatorfrcrange="-100 100" />
                <geom type="mesh" mesh="link5" name="link5_collision_0" />
                <body name="link6" quat="0.5 0.5 -0.5 0.5">
                  <inertial pos="9.50151e-05 0.00107831 -0.00019111" quat="0.708463 0.705104 -0.0268147 0.0137484" mass="0.314041" diaginertia="6.02857e-05 5.75589e-05 4.69904e-05" />
                  <joint name="joint6" pos="0 0 0" axis="0 0 1" range="-0.73 0.95" actuatorfrcrange="-100 100" />
                  <geom type="mesh" mesh="link6" name="link6_collision_0" />
                  <body name="link7" pos="0 -0.0235 0" quat="0.707107 0.707107 0 0">
                    <inertial pos="-0.00014 -0.0001 -0.00275" quat="0.5 0.5 -0.5 0.5" mass="1e-06" diaginertia="2e-07 1.1e-07 1.1e-07" />
                    <joint name="joint7" pos="0 0 0" axis="0 0 1" range="-1.5708 1.5708" actuatorfrcrange="-100 100" />
                    <geom type="mesh" mesh="link7" name="link7_collision_0" />
                    <body name="gripper_flange" pos="0.031 0 -0.0235" quat="0.499998 -0.5 0.500002 -0.5">
                      <inertial pos="0.000253201 -0.000322696 -0.0100829" quat="0.707107 0.707107 0 0" mass="0.047711" diaginertia="3.61411e-05 2.69594e-05 1.78242e-05" />
                      <geom type="mesh" mesh="gripper_flange" name="gripper_flange_collision_0" />
                      <body name="gripper_base" pos="0 0 0.006">
                        <inertial pos="-0.000183807 8.05033e-05 0.0321437" quat="0.999976 9.08444e-05 0.00689649 0.000788512" mass="0.45" diaginertia="0.000929442 0.000714469 0.000394318" />
                        <geom type="mesh" mesh="gripper_base" name="gripper_base_collision_0" />
                        <body name="gripper_link" />
                        <body name="gripper_link1" pos="0 0 0.138" quat="1.89469e-08 1.89469e-08 0.707107 0.707107">
                          <inertial pos="0.000651232 -0.049193 0.00972259" quat="0.477798 0.572974 -0.518028 0.418398" mass="0.025" diaginertia="7.74531e-05 7.36783e-05 5.0886e-06" />
                          <geom type="mesh" mesh="gripper_link1" name="gripper_link1_collision_0" />
                        </body>
                        <body name="gripper_link2" pos="0 0 0.138" quat="0.707107 0.707107 0 0">
                          <inertial pos="0.000651232 -0.049193 0.00972259" quat="0.477798 0.572974 -0.518028 0.418398" mass="0.025" diaginertia="7.74531e-05 7.36783e-05 5.0886e-06" />
                          <geom type="mesh" mesh="gripper_link2" name="gripper_link2_collision_0" />
                        </body>
                      </body>
                    </body>
                  </body>
                </body>
              </body>
            </body>
          </body>
        </body>
      </body>
    </body>
    <geom name="world_ee_path_0" type="sphere" pos="-0.158809970153 -0.102668950485 0.527942702075" size="0.006" rgba="1 0.58 0.05 0.9" contype="0" conaffinity="0" group="4" />
    <geom name="world_ee_path_1" type="sphere" pos="-0.166007574357 -0.0926874598382 0.524459673873" size="0.006" rgba="1 0.58 0.05 0.9" contype="0" conaffinity="0" group="4" />
    <geom name="world_ee_path_2" type="sphere" pos="-0.171745678263 -0.0821409976617 0.520744979627" size="0.006" rgba="1 0.58 0.05 0.9" contype="0" conaffinity="0" group="4" />
    <geom name="world_ee_path_3" type="sphere" pos="-0.175755966765 -0.0715585585281 0.517193554468" size="0.006" rgba="1 0.58 0.05 0.9" contype="0" conaffinity="0" group="4" />
    <geom name="world_ee_path_4" type="sphere" pos="-0.178081899754 -0.0615988400431 0.514161684624" size="0.006" rgba="1 0.58 0.05 0.9" contype="0" conaffinity="0" group="4" />
    <geom name="world_ee_path_5" type="sphere" pos="-0.179066670666 -0.0529259523108 0.511922036114" size="0.006" rgba="1 0.58 0.05 0.9" contype="0" conaffinity="0" group="4" />
    <geom name="world_ee_path_6" type="sphere" pos="-0.179277919434 -0.0460880605545 0.510630600351" size="0.006" rgba="1 0.58 0.05 0.9" contype="0" conaffinity="0" group="4" />
    <geom name="world_ee_path_7" type="sphere" pos="-0.179389690631 -0.0414373022154 0.510305036974" size="0.006" rgba="1 0.58 0.05 0.9" contype="0" conaffinity="0" group="4" />
    <geom name="world_ee_path_8" type="sphere" pos="-0.180053793687 -0.0391078207567 0.510815395134" size="0.006" rgba="1 0.58 0.05 0.9" contype="0" conaffinity="0" group="4" />
    <geom name="world_ee_path_9" type="sphere" pos="-0.181789247245 -0.039044162908 0.511890736882" size="0.006" rgba="1 0.58 0.05 0.9" contype="0" conaffinity="0" group="4" />
    <geom name="world_ee_path_10" type="sphere" pos="-0.184904909424 -0.0410562740454 0.513146187007" size="0.006" rgba="1 0.58 0.05 0.9" contype="0" conaffinity="0" group="4" />
    <geom name="world_ee_path_11" type="sphere" pos="-0.189457278861 -0.0448737472528 0.514132971797" size="0.006" rgba="1 0.58 0.05 0.9" contype="0" conaffinity="0" group="4" />
    <geom name="world_ee_path_12" type="sphere" pos="-0.195240371942 -0.0501785254353 0.514409129546" size="0.006" rgba="1 0.58 0.05 0.9" contype="0" conaffinity="0" group="4" />
    <geom name="world_ee_path_13" type="sphere" pos="-0.201807300492 -0.0566084060334 0.513621724286" size="0.006" rgba="1 0.58 0.05 0.9" contype="0" conaffinity="0" group="4" />
    <geom name="world_ee_path_14" type="sphere" pos="-0.208526762101 -0.0637401323142 0.511584304805" size="0.006" rgba="1 0.58 0.05 0.9" contype="0" conaffinity="0" group="4" />
    <geom name="world_ee_path_15" type="sphere" pos="-0.214674282177 -0.0710749593295 0.508329032399" size="0.006" rgba="1 0.58 0.05 0.9" contype="0" conaffinity="0" group="4" />
    <geom name="world_ee_path_16" type="sphere" pos="-0.219546174572 -0.0780530935944 0.504115138374" size="0.006" rgba="1 0.58 0.05 0.9" contype="0" conaffinity="0" group="4" />
    <geom name="world_ee_path_17" type="sphere" pos="-0.222571449301 -0.084111099174 0.499386137746" size="0.006" rgba="1 0.58 0.05 0.9" contype="0" conaffinity="0" group="4" />
    <geom name="world_ee_path_18" type="sphere" pos="-0.22339429978 -0.0887729041418 0.494684775869" size="0.006" rgba="1 0.58 0.05 0.9" contype="0" conaffinity="0" group="4" />
    <geom name="world_ee_path_19" type="sphere" pos="-0.221911296543 -0.091744076034 0.490549706592" size="0.006" rgba="1 0.58 0.05 0.9" contype="0" conaffinity="0" group="4" />
    <geom name="world_ee_path_20" type="sphere" pos="-0.21826554753 -0.0929733523179 0.487423615456" size="0.006" rgba="1 0.58 0.05 0.9" contype="0" conaffinity="0" group="4" />
    <geom name="world_ee_path_21" type="sphere" pos="-0.212812802994 -0.0926574884003 0.485595750793" size="0.006" rgba="1 0.58 0.05 0.9" contype="0" conaffinity="0" group="4" />
    <geom name="world_ee_path_22" type="sphere" pos="-0.206075703341 -0.0911871480958 0.485186226947" size="0.006" rgba="1 0.58 0.05 0.9" contype="0" conaffinity="0" group="4" />
    <geom name="world_ee_path_23" type="sphere" pos="-0.198695512829 -0.0890513491146 0.486163221321" size="0.006" rgba="1 0.58 0.05 0.9" contype="0" conaffinity="0" group="4" />
    <geom name="world_ee_path_24" type="sphere" pos="-0.191383239807 -0.0867283857634 0.488375179056" size="0.006" rgba="1 0.58 0.05 0.9" contype="0" conaffinity="0" group="4" />
    <geom name="world_ee_path_25" type="sphere" pos="-0.18486845854 -0.0845909214178 0.491581457755" size="0.006" rgba="1 0.58 0.05 0.9" contype="0" conaffinity="0" group="4" />
    <geom name="world_ee_path_26" type="sphere" pos="-0.179843980057 -0.0828452221913 0.495473605761" size="0.006" rgba="1 0.58 0.05 0.9" contype="0" conaffinity="0" group="4" />
    <geom name="world_ee_path_27" type="sphere" pos="-0.17690571387 -0.0815137460471 0.499689520473" size="0.006" rgba="1 0.58 0.05 0.9" contype="0" conaffinity="0" group="4" />
    <geom name="world_ee_path_28" type="sphere" pos="-0.176489211432 -0.0804598809874 0.503828957042" size="0.006" rgba="1 0.58 0.05 0.9" contype="0" conaffinity="0" group="4" />
    <geom name="world_ee_path_29" type="sphere" pos="-0.17880846239 -0.0794451393653 0.507479566156" size="0.006" rgba="1 0.58 0.05 0.9" contype="0" conaffinity="0" group="4" />
    <geom name="world_ee_path_30" type="sphere" pos="-0.183808252387 -0.078203304165 0.51025873851" size="0.006" rgba="1 0.58 0.05 0.9" contype="0" conaffinity="0" group="4" />
    <geom name="world_ee_path_31" type="sphere" pos="-0.191145724974 -0.0765138166878 0.511869480958" size="0.006" rgba="1 0.58 0.05 0.9" contype="0" conaffinity="0" group="4" />
    <geom name="world_ee_path_32" type="sphere" pos="-0.200215314321 -0.0742588610783 0.512159977282" size="0.006" rgba="1 0.58 0.05 0.9" contype="0" conaffinity="0" group="4" />
    <geom name="world_ee_path_33" type="sphere" pos="-0.210221629123 -0.0714544724516 0.511169438584" size="0.006" rgba="1 0.58 0.05 0.9" contype="0" conaffinity="0" group="4" />
    <geom name="world_ee_path_34" type="sphere" pos="-0.22028973218 -0.0682532033151 0.509141705459" size="0.006" rgba="1 0.58 0.05 0.9" contype="0" conaffinity="0" group="4" />
    <geom name="world_ee_path_35" type="sphere" pos="-0.229588500876 -0.0649217905811 0.506495574643" size="0.006" rgba="1 0.58 0.05 0.9" contype="0" conaffinity="0" group="4" />
    <geom name="world_ee_path_36" type="sphere" pos="-0.237437589599 -0.0618006189229 0.503754851531" size="0.006" rgba="1 0.58 0.05 0.9" contype="0" conaffinity="0" group="4" />
    <geom name="world_ee_path_37" type="sphere" pos="-0.243374681041 -0.059252950388 0.501455058669" size="0.006" rgba="1 0.58 0.05 0.9" contype="0" conaffinity="0" group="4" />
    <geom name="world_ee_path_38" type="sphere" pos="-0.247173836596 -0.057611860374 0.500050766193" size="0.006" rgba="1 0.58 0.05 0.9" contype="0" conaffinity="0" group="4" />
    <geom name="world_ee_path_39" type="sphere" pos="-0.248820950137 -0.0571321757755 0.499845087096" size="0.006" rgba="1 0.58 0.05 0.9" contype="0" conaffinity="0" group="4" />
    <geom name="world_ee_path_40" type="sphere" pos="-0.248462451849 -0.0579535288513 0.500953601726" size="0.006" rgba="1 0.58 0.05 0.9" contype="0" conaffinity="0" group="4" />
    <geom name="world_ee_path_41" type="sphere" pos="-0.246345885522 -0.0600789307054 0.503304075084" size="0.006" rgba="1 0.58 0.05 0.9" contype="0" conaffinity="0" group="4" />
    <geom name="world_ee_path_42" type="sphere" pos="-0.242766813223 -0.0633712706418 0.50666524681" size="0.006" rgba="1 0.58 0.05 0.9" contype="0" conaffinity="0" group="4" />
    <geom name="world_ee_path_43" type="sphere" pos="-0.238028868609 -0.0675681473938 0.510694434698" size="0.006" rgba="1 0.58 0.05 0.9" contype="0" conaffinity="0" group="4" />
    <geom name="world_ee_path_44" type="sphere" pos="-0.232416367613 -0.0723134364 0.514993889444" size="0.006" rgba="1 0.58 0.05 0.9" contype="0" conaffinity="0" group="4" />
    <geom name="world_ee_path_45" type="sphere" pos="-0.22617465972 -0.0772017893293 0.51916780792" size="0.006" rgba="1 0.58 0.05 0.9" contype="0" conaffinity="0" group="4" />
    <geom name="world_ee_path_46" type="sphere" pos="-0.219493767862 -0.0818299966931 0.522873914382" size="0.006" rgba="1 0.58 0.05 0.9" contype="0" conaffinity="0" group="4" />
    <geom name="world_ee_path_47" type="sphere" pos="-0.212495039994 -0.085847683999 0.525864760446" size="0.006" rgba="1 0.58 0.05 0.9" contype="0" conaffinity="0" group="4" />
    <geom name="world_ee_path_48" type="sphere" pos="-0.205225540245 -0.0890001515808 0.528014606135" size="0.006" rgba="1 0.58 0.05 0.9" contype="0" conaffinity="0" group="4" />
    <geom name="world_ee_path_49" type="sphere" pos="-0.19766688865 -0.0911582600774 0.529328804521" size="0.006" rgba="1 0.58 0.05 0.9" contype="0" conaffinity="0" group="4" />
    <geom name="world_ee_path_50" type="sphere" pos="-0.189762019097 -0.092332734296 0.529934812402" size="0.006" rgba="1 0.58 0.05 0.9" contype="0" conaffinity="0" group="4" />
    <geom name="world_ee_path_51" type="sphere" pos="-0.181456215056 -0.0926717948793 0.530057148088" size="0.006" rgba="1 0.58 0.05 0.9" contype="0" conaffinity="0" group="4" />
    <geom name="world_ee_path_52" type="sphere" pos="-0.172741972697 -0.0924419226346 0.529981477118" size="0.006" rgba="1 0.58 0.05 0.9" contype="0" conaffinity="0" group="4" />
    <geom name="world_ee_path_53" type="sphere" pos="-0.163694791513 -0.0919932644192 0.530013904193" size="0.006" rgba="1 0.58 0.05 0.9" contype="0" conaffinity="0" group="4" />
    <geom name="world_ee_path_54" type="sphere" pos="-0.154490210742 -0.0917142090564 0.530440153148" size="0.006" rgba="1 0.58 0.05 0.9" contype="0" conaffinity="0" group="4" />
    <geom name="world_ee_path_55" type="sphere" pos="-0.145399298729 -0.0919825018305 0.531487232995" size="0.006" rgba="1 0.58 0.05 0.9" contype="0" conaffinity="0" group="4" />
    <geom name="world_ee_path_56" type="sphere" pos="-0.136766452259 -0.093120859599 0.533289628421" size="0.006" rgba="1 0.58 0.05 0.9" contype="0" conaffinity="0" group="4" />
    <geom name="world_ee_path_57" type="sphere" pos="-0.128976322784 -0.0953629507441 0.535863576903" size="0.006" rgba="1 0.58 0.05 0.9" contype="0" conaffinity="0" group="4" />
    <geom name="world_ee_path_58" type="sphere" pos="-0.12241520481 -0.0988323559169 0.539094738163" size="0.006" rgba="1 0.58 0.05 0.9" contype="0" conaffinity="0" group="4" />
    <geom name="world_ee_path_59" type="sphere" pos="-0.117428839901 -0.103534562651 0.542744035039" size="0.006" rgba="1 0.58 0.05 0.9" contype="0" conaffinity="0" group="4" />
    <geom name="world_ee_path_60" type="sphere" pos="-0.114277129524 -0.109360729565 0.546473090009" size="0.006" rgba="1 0.58 0.05 0.9" contype="0" conaffinity="0" group="4" />
    <geom name="world_ee_path_61" type="sphere" pos="-0.113088547406 -0.116101347323 0.549886366551" size="0.006" rgba="1 0.58 0.05 0.9" contype="0" conaffinity="0" group="4" />
    <geom name="world_ee_path_62" type="sphere" pos="-0.113821447897 -0.123467533946 0.552584114019" size="0.006" rgba="1 0.58 0.05 0.9" contype="0" conaffinity="0" group="4" />
    <geom name="world_ee_path_63" type="sphere" pos="-0.116242529597 -0.131117534293 0.554219067003" size="0.006" rgba="1 0.58 0.05 0.9" contype="0" conaffinity="0" group="4" />
    <geom name="world_ee_path_64" type="sphere" pos="-0.119932090388 -0.138686100912 0.554549490525" size="0.006" rgba="1 0.58 0.05 0.9" contype="0" conaffinity="0" group="4" />
    <geom name="world_ee_path_65" type="sphere" pos="-0.124321354863 -0.145814606517 0.553480640155" size="0.006" rgba="1 0.58 0.05 0.9" contype="0" conaffinity="0" group="4" />
    <geom name="world_ee_path_66" type="sphere" pos="-0.128760337478 -0.152179706158 0.551086523907" size="0.006" rgba="1 0.58 0.05 0.9" contype="0" conaffinity="0" group="4" />
    <geom name="world_ee_path_67" type="sphere" pos="-0.132606956083 -0.157518040503 0.547605632439" size="0.006" rgba="1 0.58 0.05 0.9" contype="0" conaffinity="0" group="4" />
    <geom name="world_ee_path_68" type="sphere" pos="-0.135321430561 -0.161644036972 0.54340916015" size="0.006" rgba="1 0.58 0.05 0.9" contype="0" conaffinity="0" group="4" />
    <geom name="world_ee_path_69" type="sphere" pos="-0.13654706574 -0.164457867283 0.538947181765" size="0.006" rgba="1 0.58 0.05 0.9" contype="0" conaffinity="0" group="4" />
    <geom name="world_ee_path_70" type="sphere" pos="-0.136161337232 -0.165941801638 0.53468414982" size="0.006" rgba="1 0.58 0.05 0.9" contype="0" conaffinity="0" group="4" />
    <geom name="world_ee_path_71" type="sphere" pos="-0.134289160786 -0.166145853693 0.531036726076" size="0.006" rgba="1 0.58 0.05 0.9" contype="0" conaffinity="0" group="4" />
    <geom name="world_ee_path_72" type="sphere" pos="-0.13127986134 -0.165166921616 0.528323664021" size="0.006" rgba="1 0.58 0.05 0.9" contype="0" conaffinity="0" group="4" />
    <geom name="world_ee_path_73" type="sphere" pos="-0.127656426693 -0.163127800266 0.526731760719" size="0.006" rgba="1 0.58 0.05 0.9" contype="0" conaffinity="0" group="4" />
    <geom name="world_ee_path_74" type="sphere" pos="-0.124047747372 -0.160161711507 0.526297596567" size="0.006" rgba="1 0.58 0.05 0.9" contype="0" conaffinity="0" group="4" />
    <geom name="world_ee_path_75" type="sphere" pos="-0.121112417233 -0.156403949372 0.526904034767" size="0.006" rgba="1 0.58 0.05 0.9" contype="0" conaffinity="0" group="4" />
    <geom name="world_ee_path_76" type="sphere" pos="-0.119459446656 -0.151986548602 0.528292344703" size="0.006" rgba="1 0.58 0.05 0.9" contype="0" conaffinity="0" group="4" />
    <geom name="world_ee_path_77" type="sphere" pos="-0.119570426176 -0.14702810619 0.530092367365" size="0.006" rgba="1 0.58 0.05 0.9" contype="0" conaffinity="0" group="4" />
    <geom name="world_ee_path_78" type="sphere" pos="-0.121730492584 -0.141612809129 0.531871697344" size="0.006" rgba="1 0.58 0.05 0.9" contype="0" conaffinity="0" group="4" />
    <geom name="world_ee_path_79" type="sphere" pos="-0.125979371856 -0.135761510428 0.533199991082" size="0.006" rgba="1 0.58 0.05 0.9" contype="0" conaffinity="0" group="4" />
    <geom name="world_ee_path_80" type="sphere" pos="-0.132094275321 -0.129409370355 0.533718309374" size="0.006" rgba="1 0.58 0.05 0.9" contype="0" conaffinity="0" group="4" />
    <geom name="world_ee_path_81" type="sphere" pos="-0.13961131137 -0.122410877529 0.533199174976" size="0.006" rgba="1 0.58 0.05 0.9" contype="0" conaffinity="0" group="4" />
    <geom name="world_ee_path_82" type="sphere" pos="-0.14788407992 -0.114586820369 0.531583406421" size="0.006" rgba="1 0.58 0.05 0.9" contype="0" conaffinity="0" group="4" />
    <geom name="world_ee_path_83" type="sphere" pos="-0.156172091426 -0.10580917523 0.528985262013" size="0.006" rgba="1 0.58 0.05 0.9" contype="0" conaffinity="0" group="4" />
  </worldbody>
</mujoco>