<?xml version='1.0' encoding='utf-8'?>
<mujoco model="Nero Fourier excitation scene">
  <compiler angle="radian" autolimits="true" />
  <option gravity="0 0 -9.81" integrator="implicitfast" />
  <statistic center="0 0 0.4" extent="0.8" />
  <visual>
    <headlight diffuse="0.6 0.6 0.6" ambient="0.3 0.3 0.3" specular="0 0 0" />
    <rgba haze="0.15 0.25 0.35 1" />
    <global azimuth="-140" elevation="-30" />
  </visual>
  <asset>
    <texture type="skybox" builtin="flat" rgb1="0 0 0" rgb2="0 0 0" width="512" height="3072" />
    <texture type="2d" name="groundplane" builtin="checker" mark="edge" rgb1="0.2 0.3 0.4" rgb2="0.1 0.2 0.3" markrgb="0.8 0.8 0.8" width="300" height="300" />
    <material name="groundplane" texture="groundplane" texuniform="true" texrepeat="5 5" reflectance="0.2" />
    <mesh name="base_link" file="/mnt/code/lcx/Nero_collection/urdf/nero/meshes/base_link.stl" />
    <mesh name="link1" file="/mnt/code/lcx/Nero_collection/urdf/nero/meshes/link1.stl" />
    <mesh name="link2" file="/mnt/code/lcx/Nero_collection/urdf/nero/meshes/link2.stl" />
    <mesh name="link3" file="/mnt/code/lcx/Nero_collection/urdf/nero/meshes/link3.stl" />
    <mesh name="link4" file="/mnt/code/lcx/Nero_collection/urdf/nero/meshes/link4.stl" />
    <mesh name="link5" file="/mnt/code/lcx/Nero_collection/urdf/nero/meshes/link5.stl" />
    <mesh name="link6" file="/mnt/code/lcx/Nero_collection/urdf/nero/meshes/link6.stl" />
    <mesh name="link7" file="/mnt/code/lcx/Nero_collection/urdf/nero/meshes/link7.stl" />
    <mesh name="gripper_flange" file="/mnt/code/lcx/Nero_collection/urdf/nero/meshes/gripper_flange.stl" />
    <mesh name="gripper_base" file="/mnt/code/lcx/Nero_collection/urdf/nero/meshes/gripper_base.stl" />
    <mesh name="gripper_link1" file="/mnt/code/lcx/Nero_collection/urdf/nero/meshes/gripper_link1.stl" />
    <mesh name="gripper_link2" file="/mnt/code/lcx/Nero_collection/urdf/nero/meshes/gripper_link2.stl" />
  </asset>
  <worldbody>
    <light pos="0 0 1.5" dir="0 0 -1" directional="true" />
    <geom name="world_floor" size="0 0 0.05" type="plane" material="groundplane" pos="0 0 -0.02" />
    <body name="base_link">
      <inertial pos="-0.00319466 -5.46761e-05 0.0432176" quat="0.712681 0.00763931 0.0100067 0.701375" mass="1.06458" diaginertia="0.00114403 0.00102664 0.000908653" />
      <geom type="mesh" mesh="base_link" name="base_link_collision_0" />
      <body name="link1" pos="0 0 0.138">
        <inertial pos="-0.000768106 -5.71803e-05 -0.00686373" quat="0.998496 0.0243284 -0.0474034 0.0129308" mass="0.767105" diaginertia="0.000668361 0.000545022 0.000513619" />
        <joint name="joint1" pos="0 0 0" axis="0 0 1" range="-2.70526 2.70526" actuatorfrcrange="-100 100" />
        <geom type="mesh" mesh="link1" name="link1_collision_0" />
        <body name="link2" quat="1.89469e-08 1.89469e-08 0.707107 -0.707107">
          <inertial pos="0.000796867 -0.0789033 0.00111849" quat="0.724173 0.689546 -0.00281155 -0.00963045" mass="0.693819" diaginertia="0.00201137 0.00182229 0.000632162" />
          <joint name="joint2" pos="0 0 0" axis="0 0 1" range="-1.74 1.74" actuatorfrcrange="-100 100" />
          <geom type="mesh" mesh="link2" name="link2_collision_0" />
          <body name="link3" pos="0 -0.31 0" quat="-1.37922e-08 1.37922e-08 -0.707107 0.707107">
            <inertial pos="0.000145134 -0.00121379 -0.0486114" quat="0.999978 -0.00572699 -0.000503892 -0.00336231" mass="0.672465" diaginertia="0.0034323 0.00338703 0.000288126" />
            <joint name="joint3" pos="0 0 0" axis="0 0 1" range="-2.75 2.75" actuatorfrcrange="-100 100" />
            <geom type="mesh" mesh="link3" name="link3_collision_0" />
            <body name="link4" quat="-1.37922e-08 1.37922e-08 -0.707107 0.707107">
              <inertial pos="-0.000313346 -0.0567519 0.000760561" quat="0.743967 0.668141 -0.00555621 -0.00837616" mass="0.484514" diaginertia="0.000503972 0.000403451 0.00023296" />
              <joint name="joint4" pos="0 0 0" axis="0 0 1" range="-1.01 2.14" actuatorfrcrange="-100 100" />
              <geom type="mesh" mesh="link4" name="link4_collision_0" />
              <body name="link5" pos="0 -0.27001 0" quat="0.5 0.5 -0.5 0.5">
                <inertial pos="0.00265591 0.00201196 -0.116209" quat="0.994383 -0.0299767 0.0135244 0.100607" mass="0.583684" diaginertia="0.000897188 0.000859677 0.000214923" />
                <joint name="joint5" pos="0 0 0" axis="0 0 1" range="-2.75 2.75" actuatorfrcrange="-100 100" />
                <geom type="mesh" mesh="link5" name="link5_collision_0" />
                <body name="link6" quat="0.5 0.5 -0.5 0.5">
                  <inertial pos="9.50151e-05 0.00107831 -0.00019111" quat="0.708463 0.705104 -0.0268147 0.0137484" mass="0.314041" diaginertia="6.02857e-05 5.75589e-05 4.69904e-05" />
                  <joint name="joint6" pos="0 0 0" axis="0 0 1" range="-0.73 0.95" actuatorfrcrange="-100 100" />
                  <geom type="mesh" mesh="link6" name="link6_collision_0" />
                  <body name="link7" pos="0 -0.0235 0" quat="0.707107 0.707107 0 0">
                    <inertial pos="-0.00014 -0.0001 -0.00275" quat="0.5 0.5 -0.5 0.5" mass="1e-06" diaginertia="2e-07 1.1e-07 1.1e-07" />
                    <joint name="joint7" pos="0 0 0" axis="0 0 1" range="-1.5708 1.5708" actuatorfrcrange="-100 100" />
                    <geom type="mesh" mesh="link7" name="link7_collision_0" />
                    <body name="gripper_flange" pos="0.031 0 -0.0235" quat="0.499998 -0.5 0.500002 -0.5">
                      <inertial pos="0.000253201 -0.000322696 -0.0100829" quat="0.707107 0.707107 0 0" mass="0.047711" diaginertia="3.61411e-05 2.69594e-05 1.78242e-05" />
                      <geom type="mesh" mesh="gripper_flange" name="gripper_flange_collision_0" />
                      <body name="gripper_base" pos="0 0 0.006">
                        <inertial pos="-0.000183807 8.05033e-05 0.0321437" quat="0.999976 9.08444e-05 0.00689649 0.000788512" mass="0.45" diaginertia="0.000929442 0.000714469 0.000394318" />
                        <geom type="mesh" mesh="gripper_base" name="gripper_base_collision_0" />
                        <body name="gripper_link" />
                        <body name="gripper_link1" pos="0 0 0.138" quat="1.89469e-08 1.89469e-08 0.707107 0.707107">
                          <inertial pos="0.000651232 -0.049193 0.00972259" quat="0.477798 0.572974 -0.518028 0.418398" mass="0.025" diaginertia="7.74531e-05 7.36783e-05 5.0886e-06" />
                          <geom type="mesh" mesh="gripper_link1" name="gripper_link1_collision_0" />
                        </body>
                        <body name="gripper_link2" pos="0 0 0.138" quat="0.707107 0.707107 0 0">
                          <inertial pos="0.000651232 -0.049193 0.00972259" quat="0.477798 0.572974 -0.518028 0.418398" mass="0.025" diaginertia="7.74531e-05 7.36783e-05 5.0886e-06" />
                          <geom type="mesh" mesh="gripper_link2" name="gripper_link2_collision_0" />
                        </body>
                      </body>
                    </body>
                  </body>
                </body>
              </body>
            </body>
          </body>
        </body>
      </body>
    </body>
    <geom name="world_ee_path_0" type="sphere" pos="-0.15776028837 -0.115653608197 0.564745894939" size="0.006" rgba="1 0.58 0.05 0.9" contype="0" conaffinity="0" group="4" />
    <geom name="world_ee_path_1" type="sphere" pos="-0.159114256146 -0.10976293978 0.567612707565" size="0.006" rgba="1 0.58 0.05 0.9" contype="0" conaffinity="0" group="4" />
    <geom name="world_ee_path_2" type="sphere" pos="-0.158947107397 -0.107088034619 0.570074614012" size="0.006" rgba="1 0.58 0.05 0.9" contype="0" conaffinity="0" group="4" />
    <geom name="world_ee_path_3" type="sphere" pos="-0.157408794745 -0.107900538978 0.572089856515" size="0.006" rgba="1 0.58 0.05 0.9" contype="0" conaffinity="0" group="4" />
    <geom name="world_ee_path_4" type="sphere" pos="-0.154675503011 -0.112062994819 0.573572948786" size="0.006" rgba="1 0.58 0.05 0.9" contype="0" conaffinity="0" group="4" />
    <geom name="world_ee_path_5" type="sphere" pos="-0.15093814902 -0.119067989984 0.574404599179" size="0.006" rgba="1 0.58 0.05 0.9" contype="0" conaffinity="0" group="4" />
    <geom name="world_ee_path_6" type="sphere" pos="-0.146444517292 -0.128125149544 0.574456472166" size="0.006" rgba="1 0.58 0.05 0.9" contype="0" conaffinity="0" group="4" />
    <geom name="world_ee_path_7" type="sphere" pos="-0.141550891164 -0.13828062901 0.573626577943" size="0.006" rgba="1 0.58 0.05 0.9" contype="0" conaffinity="0" group="4" />
    <geom name="world_ee_path_8" type="sphere" pos="-0.136733196696 -0.148549254312 0.571877175552" size="0.006" rgba="1 0.58 0.05 0.9" contype="0" conaffinity="0" group="4" />
    <geom name="world_ee_path_9" type="sphere" pos="-0.132529030201 -0.158035141415 0.569264917584" size="0.006" rgba="1 0.58 0.05 0.9" contype="0" conaffinity="0" group="4" />
    <geom name="world_ee_path_10" type="sphere" pos="-0.129418827894 -0.166021338774 0.565953890364" size="0.006" rgba="1 0.58 0.05 0.9" contype="0" conaffinity="0" group="4" />
    <geom name="world_ee_path_11" type="sphere" pos="-0.12768750584 -0.172024080313 0.562206423693" size="0.006" rgba="1 0.58 0.05 0.9" contype="0" conaffinity="0" group="4" />
    <geom name="world_ee_path_12" type="sphere" pos="-0.127321011322 -0.175821956739 0.558352494768" size="0.006" rgba="1 0.58 0.05 0.9" contype="0" conaffinity="0" group="4" />
    <geom name="world_ee_path_13" type="sphere" pos="-0.127980733728 -0.177471727985 0.554743766871" size="0.006" rgba="1 0.58 0.05 0.9" contype="0" conaffinity="0" group="4" />
    <geom name="world_ee_path_14" type="sphere" pos="-0.129069318177 -0.177309153298 0.551701198742" size="0.006" rgba="1 0.58 0.05 0.9" contype="0" conaffinity="0" group="4" />
    <geom name="world_ee_path_15" type="sphere" pos="-0.129866832776 -0.175918307062 0.549465754089" size="0.006" rgba="1 0.58 0.05 0.9" contype="0" conaffinity="0" group="4" />
    <geom name="world_ee_path_16" type="sphere" pos="-0.129690674355 -0.17405268283 0.548160729484" size="0.006" rgba="1 0.58 0.05 0.9" contype="0" conaffinity="0" group="4" />
    <geom name="world_ee_path_17" type="sphere" pos="-0.128027676835 -0.172510039552 0.547771930376" size="0.006" rgba="1 0.58 0.05 0.9" contype="0" conaffinity="0" group="4" />
    <geom name="world_ee_path_18" type="sphere" pos="-0.124605377494 -0.171987950314 0.548148472137" size="0.006" rgba="1 0.58 0.05 0.9" contype="0" conaffinity="0" group="4" />
    <geom name="world_ee_path_19" type="sphere" pos="-0.119400915939 -0.172960280992 0.549023048271" size="0.006" rgba="1 0.58 0.05 0.9" contype="0" conaffinity="0" group="4" />
    <geom name="world_ee_path_20" type="sphere" pos="-0.112612012981 -0.175607908211 0.550047411028" size="0.006" rgba="1 0.58 0.05 0.9" contype="0" conaffinity="0" group="4" />
    <geom name="world_ee_path_21" type="sphere" pos="-0.104620771708 -0.179816103433 0.55083758854" size="0.006" rgba="1 0.58 0.05 0.9" contype="0" conaffinity="0" group="4" />
    <geom name="world_ee_path_22" type="sphere" pos="-0.0959673380721 -0.18522894019 0.551023831526" size="0.006" rgba="1 0.58 0.05 0.9" contype="0" conaffinity="0" group="4" />
    <geom name="world_ee_path_23" type="sphere" pos="-0.0873286962059 -0.191336509832 0.550301108237" size="0.006" rgba="1 0.58 0.05 0.9" contype="0" conaffinity="0" group="4" />
    <geom name="world_ee_path_24" type="sphere" pos="-0.0794829143622 -0.197565533037 0.548475836116" size="0.006" rgba="1 0.58 0.05 0.9" contype="0" conaffinity="0" group="4" />
    <geom name="world_ee_path_25" type="sphere" pos="-0.0732395964427 -0.203347627551 0.545503407829" size="0.006" rgba="1 0.58 0.05 0.9" contype="0" conaffinity="0" group="4" />
    <geom name="world_ee_path_26" type="sphere" pos="-0.0693316605108 -0.208152249332 0.541510229008" size="0.006" rgba="1 0.58 0.05 0.9" contype="0" conaffinity="0" group="4" />
    <geom name="world_ee_path_27" type="sphere" pos="-0.0682830928813 -0.211491238814 0.536794758206" size="0.006" rgba="1 0.58 0.05 0.9" contype="0" conaffinity="0" group="4" />
    <geom name="world_ee_path_28" type="sphere" pos="-0.0702828896955 -0.212920740605 0.531804490607" size="0.006" rgba="1 0.58 0.05 0.9" contype="0" conaffinity="0" group="4" />
    <geom name="world_ee_path_29" type="sphere" pos="-0.0751025851877 -0.21207143663 0.527089007471" size="0.006" rgba="1 0.58 0.05 0.9" contype="0" conaffinity="0" group="4" />
    <geom name="world_ee_path_30" type="sphere" pos="-0.082092328886 -0.208721512548 0.523232563679" size="0.006" rgba="1 0.58 0.05 0.9" contype="0" conaffinity="0" group="4" />
    <geom name="world_ee_path_31" type="sphere" pos="-0.0902758332404 -0.202894077808 0.520773577952" size="0.006" rgba="1 0.58 0.05 0.9" contype="0" conaffinity="0" group="4" />
    <geom name="world_ee_path_32" type="sphere" pos="-0.0985354356871 -0.194931717596 0.520122864517" size="0.006" rgba="1 0.58 0.05 0.9" contype="0" conaffinity="0" group="4" />
    <geom name="world_ee_path_33" type="sphere" pos="-0.105841957149 -0.185498259086 0.521495779643" size="0.006" rgba="1 0.58 0.05 0.9" contype="0" conaffinity="0" group="4" />
    <geom name="world_ee_path_34" type="sphere" pos="-0.11145942506 -0.175488850572 0.524872807845" size="0.006" rgba="1 0.58 0.05 0.9" contype="0" conaffinity="0" group="4" />
    <geom name="world_ee_path_35" type="sphere" pos="-0.11506098897 -0.165875497924 0.529997062963" size="0.006" rgba="1 0.58 0.05 0.9" contype="0" conaffinity="0" group="4" />
    <geom name="world_ee_path_36" type="sphere" pos="-0.116729094901 -0.157544322049 0.536407609055" size="0.006" rgba="1 0.58 0.05 0.9" contype="0" conaffinity="0" group="4" />
    <geom name="world_ee_path_37" type="sphere" pos="-0.116858477542 -0.151174516366 0.543498803877" size="0.006" rgba="1 0.58 0.05 0.9" contype="0" conaffinity="0" group="4" />
    <geom name="world_ee_path_38" type="sphere" pos="-0.116010292659 -0.147176975914 0.550592139023" size="0.006" rgba="1 0.58 0.05 0.9" contype="0" conaffinity="0" group="4" />
    <geom name="world_ee_path_39" type="sphere" pos="-0.114770187369 -0.145679228394 0.557009413514" size="0.006" rgba="1 0.58 0.05 0.9" contype="0" conaffinity="0" group="4" />
    <geom name="world_ee_path_40" type="sphere" pos="-0.113647827988 -0.146532491725 0.562141773118" size="0.006" rgba="1 0.58 0.05 0.9" contype="0" conaffinity="0" group="4" />
    <geom name="world_ee_path_41" type="sphere" pos="-0.113030939864 -0.149326969 0.565513332206" size="0.006" rgba="1 0.58 0.05 0.9" contype="0" conaffinity="0" group="4" />
    <geom name="world_ee_path_42" type="sphere" pos="-0.113182915838 -0.15341878001 0.566837535703" size="0.006" rgba="1 0.58 0.05 0.9" contype="0" conaffinity="0" group="4" />
    <geom name="world_ee_path_43" type="sphere" pos="-0.114258002963 -0.157981235984 0.566060152373" size="0.006" rgba="1 0.58 0.05 0.9" contype="0" conaffinity="0" group="4" />
    <geom name="world_ee_path_44" type="sphere" pos="-0.116307963683 -0.162089151495 0.563379120886" size="0.006" rgba="1 0.58 0.05 0.9" contype="0" conaffinity="0" group="4" />
    <geom name="world_ee_path_45" type="sphere" pos="-0.119268564386 -0.164832423312 0.559232235281" size="0.006" rgba="1 0.58 0.05 0.9" contype="0" conaffinity="0" group="4" />
    <geom name="world_ee_path_46" type="sphere" pos="-0.122935150941 -0.165442455849 0.554249350906" size="0.006" rgba="1 0.58 0.05 0.9" contype="0" conaffinity="0" group="4" />
    <geom name="world_ee_path_47" type="sphere" pos="-0.126952025373 -0.163407457215 0.54917376971" size="0.006" rgba="1 0.58 0.05 0.9" contype="0" conaffinity="0" group="4" />
    <geom name="world_ee_path_48" type="sphere" pos="-0.130841324972 -0.158551334433 0.544764338285" size="0.006" rgba="1 0.58 0.05 0.9" contype="0" conaffinity="0" group="4" />
    <geom name="world_ee_path_49" type="sphere" pos="-0.134082335632 -0.151055665524 0.541693658545" size="0.006" rgba="1 0.58 0.05 0.9" contype="0" conaffinity="0" group="4" />
    <geom name="world_ee_path_50" type="sphere" pos="-0.136228741105 -0.141415570811 0.540458587169" size="0.006" rgba="1 0.58 0.05 0.9" contype="0" conaffinity="0" group="4" />
    <geom name="world_ee_path_51" type="sphere" pos="-0.137031267813 -0.130338053216 0.541317271159" size="0.006" rgba="1 0.58 0.05 0.9" contype="0" conaffinity="0" group="4" />
    <geom name="world_ee_path_52" type="sphere" pos="-0.136527201769 -0.118610755615 0.544262153841" size="0.006" rgba="1 0.58 0.05 0.9" contype="0" conaffinity="0" group="4" />
    <geom name="world_ee_path_53" type="sphere" pos="-0.135068992276 -0.106980139529 0.54903080289" size="0.006" rgba="1 0.58 0.05 0.9" contype="0" conaffinity="0" group="4" />
    <geom name="world_ee_path_54" type="sphere" pos="-0.133284269384 -0.0960721115814 0.555147978296" size="0.006" rgba="1 0.58 0.05 0.9" contype="0" conaffinity="0" group="4" />
    <geom name="world_ee_path_55" type="sphere" pos="-0.131977680745 -0.0863663277602 0.561986474273" size="0.006" rgba="1 0.58 0.05 0.9" contype="0" conaffinity="0" group="4" />
    <geom name="world_ee_path_56" type="sphere" pos="-0.13199471642 -0.0782102475486 0.568833604838" size="0.006" rgba="1 0.58 0.05 0.9" contype="0" conaffinity="0" group="4" />
    <geom name="world_ee_path_57" type="sphere" pos="-0.134070922368 -0.0718455493765 0.574954830271" size="0.006" rgba="1 0.58 0.05 0.9" contype="0" conaffinity="0" group="4" />
    <geom name="world_ee_path_58" type="sphere" pos="-0.138690990094 -0.0674245925303 0.579653220274" size="0.006" rgba="1 0.58 0.05 0.9" contype="0" conaffinity="0" group="4" />
    <geom name="world_ee_path_59" type="sphere" pos="-0.145982145391 -0.0650125909679 0.582328855146" size="0.006" rgba="1 0.58 0.05 0.9" contype="0" conaffinity="0" group="4" />
    <geom name="world_ee_path_60" type="sphere" pos="-0.155662775471 -0.0645883832365 0.58254197614" size="0.006" rgba="1 0.58 0.05 0.9" contype="0" conaffinity="0" group="4" />
    <geom name="world_ee_path_61" type="sphere" pos="-0.167058699572 -0.0660607839656 0.580076835101" size="0.006" rgba="1 0.58 0.05 0.9" contype="0" conaffinity="0" group="4" />
    <geom name="world_ee_path_62" type="sphere" pos="-0.179186851663 -0.0693056955082 0.574993333108" size="0.006" rgba="1 0.58 0.05 0.9" contype="0" conaffinity="0" group="4" />
    <geom name="world_ee_path_63" type="sphere" pos="-0.1908919898 -0.0742100981617 0.567647263907" size="0.006" rgba="1 0.58 0.05 0.9" contype="0" conaffinity="0" group="4" />
    <geom name="world_ee_path_64" type="sphere" pos="-0.2010097981 -0.0806969781973 0.558662900038" size="0.006" rgba="1 0.58 0.05 0.9" contype="0" conaffinity="0" group="4" />
    <geom name="world_ee_path_65" type="sphere" pos="-0.208523794788 -0.0887102208346 0.548854411097" size="0.006" rgba="1 0.58 0.05 0.9" contype="0" conaffinity="0" group="4" />
    <geom name="world_ee_path_66" type="sphere" pos="-0.212687603467 -0.0981590231484 0.539109775428" size="0.006" rgba="1 0.58 0.05 0.9" contype="0" conaffinity="0" group="4" />
    <geom name="world_ee_path_67" type="sphere" pos="-0.213097790693 -0.108845063426 0.530263970393" size="0.006" rgba="1 0.58 0.05 0.9" contype="0" conaffinity="0" group="4" />
    <geom name="world_ee_path_68" type="sphere" pos="-0.209718902928 -0.12040764453 0.522990942712" size="0.006" rgba="1 0.58 0.05 0.9" contype="0" conaffinity="0" group="4" />
    <geom name="world_ee_path_69" type="sphere" pos="-0.202872744094 -0.132315298368 0.517735608611" size="0.006" rgba="1 0.58 0.05 0.9" contype="0" conaffinity="0" group="4" />
    <geom name="world_ee_path_70" type="sphere" pos="-0.193204088673 -0.143911805399 0.514692940617" size="0.006" rgba="1 0.58 0.05 0.9" contype="0" conaffinity="0" group="4" />
    <geom name="world_ee_path_71" type="sphere" pos="-0.181627758741 -0.154502209945 0.513828126976" size="0.006" rgba="1 0.58 0.05 0.9" contype="0" conaffinity="0" group="4" />
    <geom name="world_ee_path_72" type="sphere" pos="-0.169253825984 -0.163450423214 0.5149246017" size="0.006" rgba="1 0.58 0.05 0.9" contype="0" conaffinity="0" group="4" />
    <geom name="world_ee_path_73" type="sphere" pos="-0.157284368635 -0.170257907581 0.517645608945" size="0.006" rgba="1 0.58 0.05 0.9" contype="0" conaffinity="0" group="4" />
    <geom name="world_ee_path_74" type="sphere" pos="-0.146879823286 -0.174601356995 0.521596879778" size="0.006" rgba="1 0.58 0.05 0.9" contype="0" conaffinity="0" group="4" />
    <geom name="world_ee_path_75" type="sphere" pos="-0.13900520924 -0.176324022272 0.526380533095" size="0.006" rgba="1 0.58 0.05 0.9" contype="0" conaffinity="0" group="4" />
    <geom name="world_ee_path_76" type="sphere" pos="-0.134281579739 -0.175396871194 0.531633631798" size="0.006" rgba="1 0.58 0.05 0.9" contype="0" conaffinity="0" group="4" />
    <geom name="world_ee_path_77" type="sphere" pos="-0.132878182378 -0.171883220899 0.537049745131" size="0.006" rgba="1 0.58 0.05 0.9" contype="0" conaffinity="0" group="4" />
    <geom name="world_ee_path_78" type="sphere" pos="-0.13447991729 -0.165940775955 0.542386995891" size="0.006" rgba="1 0.58 0.05 0.9" contype="0" conaffinity="0" group="4" />
    <geom name="world_ee_path_79" type="sphere" pos="-0.138351138383 -0.157871568676 0.547468426184" size="0.006" rgba="1 0.58 0.05 0.9" contype="0" conaffinity="0" group="4" />
    <geom name="world_ee_path_80" type="sphere" pos="-0.143492014115 -0.148193450487 0.552178886407" size="0.006" rgba="1 0.58 0.05 0.9" contype="0" conaffinity="0" group="4" />
    <geom name="world_ee_path_81" type="sphere" pos="-0.148852110805 -0.137680833099 0.5564590794" size="0.006" rgba="1 0.58 0.05 0.9" contype="0" conaffinity="0" group="4" />
    <geom name="world_ee_path_82" type="sphere" pos="-0.153539298058 -0.127328290148 0.560295039" size="0.006" rgba="1 0.58 0.05 0.9" contype="0" conaffinity="0" group="4" />
    <geom name="world_ee_path_83" type="sphere" pos="-0.15695784059 -0.118227775143 0.563701668533" size="0.006" rgba="1 0.58 0.05 0.9" contype="0" conaffinity="0" group="4" />
  </worldbody>
</mujoco>