<?xml version='1.0' encoding='utf-8'?>
<mujoco model="Nero Fourier excitation scene">
  <compiler angle="radian" autolimits="true" />
  <option gravity="0 0 -9.81" integrator="implicitfast" />
  <statistic center="0 0 0.4" extent="0.8" />
  <visual>
    <headlight diffuse="0.6 0.6 0.6" ambient="0.3 0.3 0.3" specular="0 0 0" />
    <rgba haze="0.15 0.25 0.35 1" />
    <global azimuth="-140" elevation="-30" />
  </visual>
  <asset>
    <texture type="skybox" builtin="flat" rgb1="0 0 0" rgb2="0 0 0" width="512" height="3072" />
    <texture type="2d" name="groundplane" builtin="checker" mark="edge" rgb1="0.2 0.3 0.4" rgb2="0.1 0.2 0.3" markrgb="0.8 0.8 0.8" width="300" height="300" />
    <material name="groundplane" texture="groundplane" texuniform="true" texrepeat="5 5" reflectance="0.2" />
    <mesh name="base_link" file="/mnt/code/lcx/Nero_collection/urdf/nero/meshes/base_link.stl" />
    <mesh name="link1" file="/mnt/code/lcx/Nero_collection/urdf/nero/meshes/link1.stl" />
    <mesh name="link2" file="/mnt/code/lcx/Nero_collection/urdf/nero/meshes/link2.stl" />
    <mesh name="link3" file="/mnt/code/lcx/Nero_collection/urdf/nero/meshes/link3.stl" />
    <mesh name="link4" file="/mnt/code/lcx/Nero_collection/urdf/nero/meshes/link4.stl" />
    <mesh name="link5" file="/mnt/code/lcx/Nero_collection/urdf/nero/meshes/link5.stl" />
    <mesh name="link6" file="/mnt/code/lcx/Nero_collection/urdf/nero/meshes/link6.stl" />
    <mesh name="link7" file="/mnt/code/lcx/Nero_collection/urdf/nero/meshes/link7.stl" />
    <mesh name="gripper_flange" file="/mnt/code/lcx/Nero_collection/urdf/nero/meshes/gripper_flange.stl" />
    <mesh name="gripper_base" file="/mnt/code/lcx/Nero_collection/urdf/nero/meshes/gripper_base.stl" />
    <mesh name="gripper_link1" file="/mnt/code/lcx/Nero_collection/urdf/nero/meshes/gripper_link1.stl" />
    <mesh name="gripper_link2" file="/mnt/code/lcx/Nero_collection/urdf/nero/meshes/gripper_link2.stl" />
  </asset>
  <worldbody>
    <light pos="0 0 1.5" dir="0 0 -1" directional="true" />
    <geom name="world_floor" size="0 0 0.05" type="plane" material="groundplane" pos="0 0 -0.02" />
    <body name="base_link">
      <inertial pos="-0.00319466 -5.46761e-05 0.0432176" quat="0.712681 0.00763931 0.0100067 0.701375" mass="1.06458" diaginertia="0.00114403 0.00102664 0.000908653" />
      <geom type="mesh" mesh="base_link" name="base_link_collision_0" />
      <body name="link1" pos="0 0 0.138">
        <inertial pos="-0.000768106 -5.71803e-05 -0.00686373" quat="0.998496 0.0243284 -0.0474034 0.0129308" mass="0.767105" diaginertia="0.000668361 0.000545022 0.000513619" />
        <joint name="joint1" pos="0 0 0" axis="0 0 1" range="-2.70526 2.70526" actuatorfrcrange="-100 100" />
        <geom type="mesh" mesh="link1" name="link1_collision_0" />
        <body name="link2" quat="1.89469e-08 1.89469e-08 0.707107 -0.707107">
          <inertial pos="0.000796867 -0.0789033 0.00111849" quat="0.724173 0.689546 -0.00281155 -0.00963045" mass="0.693819" diaginertia="0.00201137 0.00182229 0.000632162" />
          <joint name="joint2" pos="0 0 0" axis="0 0 1" range="-1.74 1.74" actuatorfrcrange="-100 100" />
          <geom type="mesh" mesh="link2" name="link2_collision_0" />
          <body name="link3" pos="0 -0.31 0" quat="-1.37922e-08 1.37922e-08 -0.707107 0.707107">
            <inertial pos="0.000145134 -0.00121379 -0.0486114" quat="0.999978 -0.00572699 -0.000503892 -0.00336231" mass="0.672465" diaginertia="0.0034323 0.00338703 0.000288126" />
            <joint name="joint3" pos="0 0 0" axis="0 0 1" range="-2.75 2.75" actuatorfrcrange="-100 100" />
            <geom type="mesh" mesh="link3" name="link3_collision_0" />
            <body name="link4" quat="-1.37922e-08 1.37922e-08 -0.707107 0.707107">
              <inertial pos="-0.000313346 -0.0567519 0.000760561" quat="0.743967 0.668141 -0.00555621 -0.00837616" mass="0.484514" diaginertia="0.000503972 0.000403451 0.00023296" />
              <joint name="joint4" pos="0 0 0" axis="0 0 1" range="-1.01 2.14" actuatorfrcrange="-100 100" />
              <geom type="mesh" mesh="link4" name="link4_collision_0" />
              <body name="link5" pos="0 -0.27001 0" quat="0.5 0.5 -0.5 0.5">
                <inertial pos="0.00265591 0.00201196 -0.116209" quat="0.994383 -0.0299767 0.0135244 0.100607" mass="0.583684" diaginertia="0.000897188 0.000859677 0.000214923" />
                <joint name="joint5" pos="0 0 0" axis="0 0 1" range="-2.75 2.75" actuatorfrcrange="-100 100" />
                <geom type="mesh" mesh="link5" name="link5_collision_0" />
                <body name="link6" quat="0.5 0.5 -0.5 0.5">
                  <inertial pos="9.50151e-05 0.00107831 -0.00019111" quat="0.708463 0.705104 -0.0268147 0.0137484" mass="0.314041" diaginertia="6.02857e-05 5.75589e-05 4.69904e-05" />
                  <joint name="joint6" pos="0 0 0" axis="0 0 1" range="-0.73 0.95" actuatorfrcrange="-100 100" />
                  <geom type="mesh" mesh="link6" name="link6_collision_0" />
                  <body name="link7" pos="0 -0.0235 0" quat="0.707107 0.707107 0 0">
                    <inertial pos="-0.00014 -0.0001 -0.00275" quat="0.5 0.5 -0.5 0.5" mass="1e-06" diaginertia="2e-07 1.1e-07 1.1e-07" />
                    <joint name="joint7" pos="0 0 0" axis="0 0 1" range="-1.5708 1.5708" actuatorfrcrange="-100 100" />
                    <geom type="mesh" mesh="link7" name="link7_collision_0" />
                    <body name="gripper_flange" pos="0.031 0 -0.0235" quat="0.499998 -0.5 0.500002 -0.5">
                      <inertial pos="0.000253201 -0.000322696 -0.0100829" quat="0.707107 0.707107 0 0" mass="0.047711" diaginertia="3.61411e-05 2.69594e-05 1.78242e-05" />
                      <geom type="mesh" mesh="gripper_flange" name="gripper_flange_collision_0" />
                      <body name="gripper_base" pos="0 0 0.006">
                        <inertial pos="-0.000183807 8.05033e-05 0.0321437" quat="0.999976 9.08444e-05 0.00689649 0.000788512" mass="0.45" diaginertia="0.000929442 0.000714469 0.000394318" />
                        <geom type="mesh" mesh="gripper_base" name="gripper_base_collision_0" />
                        <body name="gripper_link" />
                        <body name="gripper_link1" pos="0 0 0.138" quat="1.89469e-08 1.89469e-08 0.707107 0.707107">
                          <inertial pos="0.000651232 -0.049193 0.00972259" quat="0.477798 0.572974 -0.518028 0.418398" mass="0.025" diaginertia="7.74531e-05 7.36783e-05 5.0886e-06" />
                          <geom type="mesh" mesh="gripper_link1" name="gripper_link1_collision_0" />
                        </body>
                        <body name="gripper_link2" pos="0 0 0.138" quat="0.707107 0.707107 0 0">
                          <inertial pos="0.000651232 -0.049193 0.00972259" quat="0.477798 0.572974 -0.518028 0.418398" mass="0.025" diaginertia="7.74531e-05 7.36783e-05 5.0886e-06" />
                          <geom type="mesh" mesh="gripper_link2" name="gripper_link2_collision_0" />
                        </body>
                      </body>
                    </body>
                  </body>
                </body>
              </body>
            </body>
          </body>
        </body>
      </body>
    </body>
    <geom name="world_ee_path_0" type="sphere" pos="0.0308494259065 0.0126094196376 0.663482192574" size="0.006" rgba="1 0.58 0.05 0.9" contype="0" conaffinity="0" group="4" />
    <geom name="world_ee_path_1" type="sphere" pos="0.0304800163337 0.00671107484169 0.66304688818" size="0.006" rgba="1 0.58 0.05 0.9" contype="0" conaffinity="0" group="4" />
    <geom name="world_ee_path_2" type="sphere" pos="0.031584939783 0.00139136726169 0.662198839166" size="0.006" rgba="1 0.58 0.05 0.9" contype="0" conaffinity="0" group="4" />
    <geom name="world_ee_path_3" type="sphere" pos="0.034777221465 -0.0035555846703 0.661100998213" size="0.006" rgba="1 0.58 0.05 0.9" contype="0" conaffinity="0" group="4" />
    <geom name="world_ee_path_4" type="sphere" pos="0.0405209919227 -0.00835953921394 0.659903143078" size="0.006" rgba="1 0.58 0.05 0.9" contype="0" conaffinity="0" group="4" />
    <geom name="world_ee_path_5" type="sphere" pos="0.0490349878828 -0.0132030237724 0.658701142885" size="0.006" rgba="1 0.58 0.05 0.9" contype="0" conaffinity="0" group="4" />
    <geom name="world_ee_path_6" type="sphere" pos="0.0602285959832 -0.0181763595493 0.657517017614" size="0.006" rgba="1 0.58 0.05 0.9" contype="0" conaffinity="0" group="4" />
    <geom name="world_ee_path_7" type="sphere" pos="0.0736652898492 -0.0232785380612 0.656312151622" size="0.006" rgba="1 0.58 0.05 0.9" contype="0" conaffinity="0" group="4" />
    <geom name="world_ee_path_8" type="sphere" pos="0.0885520005404 -0.0284625223723 0.655033713389" size="0.006" rgba="1 0.58 0.05 0.9" contype="0" conaffinity="0" group="4" />
    <geom name="world_ee_path_9" type="sphere" pos="0.103763719939 -0.0336999251726 0.653679758877" size="0.006" rgba="1 0.58 0.05 0.9" contype="0" conaffinity="0" group="4" />
    <geom name="world_ee_path_10" type="sphere" pos="0.117917941238 -0.0390248541005 0.652355904746" size="0.006" rgba="1 0.58 0.05 0.9" contype="0" conaffinity="0" group="4" />
    <geom name="world_ee_path_11" type="sphere" pos="0.12950610951 -0.0445196528414 0.651291498636" size="0.006" rgba="1 0.58 0.05 0.9" contype="0" conaffinity="0" group="4" />
    <geom name="world_ee_path_12" type="sphere" pos="0.1370732639 -0.0502300033024 0.65079251537" size="0.006" rgba="1 0.58 0.05 0.9" contype="0" conaffinity="0" group="4" />
    <geom name="world_ee_path_13" type="sphere" pos="0.139423877169 -0.0560360094106 0.651134185704" size="0.006" rgba="1 0.58 0.05 0.9" contype="0" conaffinity="0" group="4" />
    <geom name="world_ee_path_14" type="sphere" pos="0.135827926096 -0.0615414163693 0.652429913849" size="0.006" rgba="1 0.58 0.05 0.9" contype="0" conaffinity="0" group="4" />
    <geom name="world_ee_path_15" type="sphere" pos="0.12619994355 -0.0660546855244 0.654535860916" size="0.006" rgba="1 0.58 0.05 0.9" contype="0" conaffinity="0" group="4" />
    <geom name="world_ee_path_16" type="sphere" pos="0.111214134931 -0.0687108103328 0.657045744129" size="0.006" rgba="1 0.58 0.05 0.9" contype="0" conaffinity="0" group="4" />
    <geom name="world_ee_path_17" type="sphere" pos="0.0923042199429 -0.0687235535658 0.659395167246" size="0.006" rgba="1 0.58 0.05 0.9" contype="0" conaffinity="0" group="4" />
    <geom name="world_ee_path_18" type="sphere" pos="0.0715021323274 -0.0656852098821 0.661043858521" size="0.006" rgba="1 0.58 0.05 0.9" contype="0" conaffinity="0" group="4" />
    <geom name="world_ee_path_19" type="sphere" pos="0.0511175499306 -0.0597845120216 0.661662828024" size="0.006" rgba="1 0.58 0.05 0.9" contype="0" conaffinity="0" group="4" />
    <geom name="world_ee_path_20" type="sphere" pos="0.0333363621373 -0.0518318659428 0.661245204077" size="0.006" rgba="1 0.58 0.05 0.9" contype="0" conaffinity="0" group="4" />
    <geom name="world_ee_path_21" type="sphere" pos="0.0198673109947 -0.0430675287496 0.660092341089" size="0.006" rgba="1 0.58 0.05 0.9" contype="0" conaffinity="0" group="4" />
    <geom name="world_ee_path_22" type="sphere" pos="0.0117449483649 -0.0348331003189 0.658684856852" size="0.006" rgba="1 0.58 0.05 0.9" contype="0" conaffinity="0" group="4" />
    <geom name="world_ee_path_23" type="sphere" pos="0.00931254368269 -0.0282423640869 0.657499350922" size="0.006" rgba="1 0.58 0.05 0.9" contype="0" conaffinity="0" group="4" />
    <geom name="world_ee_path_24" type="sphere" pos="0.0123217202973 -0.0239659291935 0.65684910711" size="0.006" rgba="1 0.58 0.05 0.9" contype="0" conaffinity="0" group="4" />
    <geom name="world_ee_path_25" type="sphere" pos="0.0200546402416 -0.022174412174 0.656807765191" size="0.006" rgba="1 0.58 0.05 0.9" contype="0" conaffinity="0" group="4" />
    <geom name="world_ee_path_26" type="sphere" pos="0.0314087887644 -0.0226173056779 0.657235381042" size="0.006" rgba="1 0.58 0.05 0.9" contype="0" conaffinity="0" group="4" />
    <geom name="world_ee_path_27" type="sphere" pos="0.0449473214369 -0.0247776358307 0.657885779801" size="0.006" rgba="1 0.58 0.05 0.9" contype="0" conaffinity="0" group="4" />
    <geom name="world_ee_path_28" type="sphere" pos="0.0589626040856 -0.0280352498849 0.658544022858" size="0.006" rgba="1 0.58 0.05 0.9" contype="0" conaffinity="0" group="4" />
    <geom name="world_ee_path_29" type="sphere" pos="0.071601290957 -0.0317841978539 0.659130152909" size="0.006" rgba="1 0.58 0.05 0.9" contype="0" conaffinity="0" group="4" />
    <geom name="world_ee_path_30" type="sphere" pos="0.0810628992374 -0.0354772996401 0.659717674886" size="0.006" rgba="1 0.58 0.05 0.9" contype="0" conaffinity="0" group="4" />
    <geom name="world_ee_path_31" type="sphere" pos="0.0858401969609 -0.0386086441169 0.660454254034" size="0.006" rgba="1 0.58 0.05 0.9" contype="0" conaffinity="0" group="4" />
    <geom name="world_ee_path_32" type="sphere" pos="0.0849472649318 -0.0406782305811 0.661423433595" size="0.006" rgba="1 0.58 0.05 0.9" contype="0" conaffinity="0" group="4" />
    <geom name="world_ee_path_33" type="sphere" pos="0.0780854228567 -0.0411932070597 0.662522070485" size="0.006" rgba="1 0.58 0.05 0.9" contype="0" conaffinity="0" group="4" />
    <geom name="world_ee_path_34" type="sphere" pos="0.0657131758435 -0.0397379048577 0.663426163104" size="0.006" rgba="1 0.58 0.05 0.9" contype="0" conaffinity="0" group="4" />
    <geom name="world_ee_path_35" type="sphere" pos="0.0490004761923 -0.0360994962464 0.663676789553" size="0.006" rgba="1 0.58 0.05 0.9" contype="0" conaffinity="0" group="4" />
    <geom name="world_ee_path_36" type="sphere" pos="0.0296632109162 -0.0303922292991 0.662858310381" size="0.006" rgba="1 0.58 0.05 0.9" contype="0" conaffinity="0" group="4" />
    <geom name="world_ee_path_37" type="sphere" pos="0.00970087738843 -0.0231083986196 0.660792350418" size="0.006" rgba="1 0.58 0.05 0.9" contype="0" conaffinity="0" group="4" />
    <geom name="world_ee_path_38" type="sphere" pos="-0.00890529199979 -0.0150521195114 0.657658289892" size="0.006" rgba="1 0.58 0.05 0.9" contype="0" conaffinity="0" group="4" />
    <geom name="world_ee_path_39" type="sphere" pos="-0.0244570596974 -0.00716913904445 0.653982328252" size="0.006" rgba="1 0.58 0.05 0.9" contype="0" conaffinity="0" group="4" />
    <geom name="world_ee_path_40" type="sphere" pos="-0.0357053992236 -0.000336995690108 0.650497156307" size="0.006" rgba="1 0.58 0.05 0.9" contype="0" conaffinity="0" group="4" />
    <geom name="world_ee_path_41" type="sphere" pos="-0.0419025140336 0.00480657184588 0.64793022808" size="0.006" rgba="1 0.58 0.05 0.9" contype="0" conaffinity="0" group="4" />
    <geom name="world_ee_path_42" type="sphere" pos="-0.0427718977429 0.00794619525354 0.646801968751" size="0.006" rgba="1 0.58 0.05 0.9" contype="0" conaffinity="0" group="4" />
    <geom name="world_ee_path_43" type="sphere" pos="-0.0384496041459 0.00907627911228 0.647300496314" size="0.006" rgba="1 0.58 0.05 0.9" contype="0" conaffinity="0" group="4" />
    <geom name="world_ee_path_44" type="sphere" pos="-0.0294353056172 0.00842270027096 0.649262910198" size="0.006" rgba="1 0.58 0.05 0.9" contype="0" conaffinity="0" group="4" />
    <geom name="world_ee_path_45" type="sphere" pos="-0.0165569327534 0.00634319960578 0.652255429996" size="0.006" rgba="1 0.58 0.05 0.9" contype="0" conaffinity="0" group="4" />
    <geom name="world_ee_path_46" type="sphere" pos="-0.00092338515831 0.00324696986726 0.655716821041" size="0.006" rgba="1 0.58 0.05 0.9" contype="0" conaffinity="0" group="4" />
    <geom name="world_ee_path_47" type="sphere" pos="0.0161651798868 -0.000443390796285 0.65911474974" size="0.006" rgba="1 0.58 0.05 0.9" contype="0" conaffinity="0" group="4" />
    <geom name="world_ee_path_48" type="sphere" pos="0.0333590401677 -0.00428939937345 0.662065201644" size="0.006" rgba="1 0.58 0.05 0.9" contype="0" conaffinity="0" group="4" />
    <geom name="world_ee_path_49" type="sphere" pos="0.0494301906259 -0.00781850659398 0.664382455376" size="0.006" rgba="1 0.58 0.05 0.9" contype="0" conaffinity="0" group="4" />
    <geom name="world_ee_path_50" type="sphere" pos="0.0634286743828 -0.010523514035 0.666056263" size="0.006" rgba="1 0.58 0.05 0.9" contype="0" conaffinity="0" group="4" />
    <geom name="world_ee_path_51" type="sphere" pos="0.0747802663157 -0.0119008331663 0.667180717363" size="0.006" rgba="1 0.58 0.05 0.9" contype="0" conaffinity="0" group="4" />
    <geom name="world_ee_path_52" type="sphere" pos="0.0833037597578 -0.011523701303 0.667872612404" size="0.006" rgba="1 0.58 0.05 0.9" contype="0" conaffinity="0" group="4" />
    <geom name="world_ee_path_53" type="sphere" pos="0.0891553726627 -0.0091245465193 0.668212032877" size="0.006" rgba="1 0.58 0.05 0.9" contype="0" conaffinity="0" group="4" />
    <geom name="world_ee_path_54" type="sphere" pos="0.0927288809533 -0.00465470363295 0.668220913141" size="0.006" rgba="1 0.58 0.05 0.9" contype="0" conaffinity="0" group="4" />
    <geom name="world_ee_path_55" type="sphere" pos="0.0945449746709 0.00169944446024 0.667876721922" size="0.006" rgba="1 0.58 0.05 0.9" contype="0" conaffinity="0" group="4" />
    <geom name="world_ee_path_56" type="sphere" pos="0.0951541405077 0.00954611881641 0.667145994241" size="0.006" rgba="1 0.58 0.05 0.9" contype="0" conaffinity="0" group="4" />
    <geom name="world_ee_path_57" type="sphere" pos="0.0950627271679 0.0183503261872 0.666019008122" size="0.006" rgba="1 0.58 0.05 0.9" contype="0" conaffinity="0" group="4" />
    <geom name="world_ee_path_58" type="sphere" pos="0.0946806317935 0.0275094321359 0.664531271678" size="0.006" rgba="1 0.58 0.05 0.9" contype="0" conaffinity="0" group="4" />
    <geom name="world_ee_path_59" type="sphere" pos="0.0942855879073 0.0364264996181 0.662766006385" size="0.006" rgba="1 0.58 0.05 0.9" contype="0" conaffinity="0" group="4" />
    <geom name="world_ee_path_60" type="sphere" pos="0.0940020201608 0.0445738157808 0.660840156379" size="0.006" rgba="1 0.58 0.05 0.9" contype="0" conaffinity="0" group="4" />
    <geom name="world_ee_path_61" type="sphere" pos="0.0937973135652 0.0515456710923 0.658881295935" size="0.006" rgba="1 0.58 0.05 0.9" contype="0" conaffinity="0" group="4" />
    <geom name="world_ee_path_62" type="sphere" pos="0.0935008925944 0.05710084848 0.657003252378" size="0.006" rgba="1 0.58 0.05 0.9" contype="0" conaffinity="0" group="4" />
    <geom name="world_ee_path_63" type="sphere" pos="0.0928496891456 0.0611913186938 0.655286129334" size="0.006" rgba="1 0.58 0.05 0.9" contype="0" conaffinity="0" group="4" />
    <geom name="world_ee_path_64" type="sphere" pos="0.0915572376021 0.0639677310559 0.653764498522" size="0.006" rgba="1 0.58 0.05 0.9" contype="0" conaffinity="0" group="4" />
    <geom name="world_ee_path_65" type="sphere" pos="0.0893939561761 0.0657498520253 0.652426856954" size="0.006" rgba="1 0.58 0.05 0.9" contype="0" conaffinity="0" group="4" />
    <geom name="world_ee_path_66" type="sphere" pos="0.0862566586034 0.0669560054299 0.651228418131" size="0.006" rgba="1 0.58 0.05 0.9" contype="0" conaffinity="0" group="4" />
    <geom name="world_ee_path_67" type="sphere" pos="0.0822024913053 0.0680004332272 0.650115913374" size="0.006" rgba="1 0.58 0.05 0.9" contype="0" conaffinity="0" group="4" />
    <geom name="world_ee_path_68" type="sphere" pos="0.0774324589284 0.0691847859191 0.649057826164" size="0.006" rgba="1 0.58 0.05 0.9" contype="0" conaffinity="0" group="4" />
    <geom name="world_ee_path_69" type="sphere" pos="0.0722312902343 0.0706181936368 0.648069611088" size="0.006" rgba="1 0.58 0.05 0.9" contype="0" conaffinity="0" group="4" />
    <geom name="world_ee_path_70" type="sphere" pos="0.0668918467596 0.0721918094227 0.647224061524" size="0.006" rgba="1 0.58 0.05 0.9" contype="0" conaffinity="0" group="4" />
    <geom name="world_ee_path_71" type="sphere" pos="0.0616585258112 0.0736122963714 0.646642116933" size="0.006" rgba="1 0.58 0.05 0.9" contype="0" conaffinity="0" group="4" />
    <geom name="world_ee_path_72" type="sphere" pos="0.056709722347 0.0744778436466 0.646466139843" size="0.006" rgba="1 0.58 0.05 0.9" contype="0" conaffinity="0" group="4" />
    <geom name="world_ee_path_73" type="sphere" pos="0.0521740117552 0.0743712088215 0.646822954091" size="0.006" rgba="1 0.58 0.05 0.9" contype="0" conaffinity="0" group="4" />
    <geom name="world_ee_path_74" type="sphere" pos="0.048155253273 0.0729473530559 0.647786530665" size="0.006" rgba="1 0.58 0.05 0.9" contype="0" conaffinity="0" group="4" />
    <geom name="world_ee_path_75" type="sphere" pos="0.0447400012089 0.0700006942524 0.6493504303" size="0.006" rgba="1 0.58 0.05 0.9" contype="0" conaffinity="0" group="4" />
    <geom name="world_ee_path_76" type="sphere" pos="0.0419763340918 0.0655025794511 0.651418138397" size="0.006" rgba="1 0.58 0.05 0.9" contype="0" conaffinity="0" group="4" />
    <geom name="world_ee_path_77" type="sphere" pos="0.0398363054588 0.0596037836759 0.653814818065" size="0.006" rgba="1 0.58 0.05 0.9" contype="0" conaffinity="0" group="4" />
    <geom name="world_ee_path_78" type="sphere" pos="0.0381907196847 0.0526033415106 0.656317090826" size="0.006" rgba="1 0.58 0.05 0.9" contype="0" conaffinity="0" group="4" />
    <geom name="world_ee_path_79" type="sphere" pos="0.0368244505468 0.0448937126838 0.658690998711" size="0.006" rgba="1 0.58 0.05 0.9" contype="0" conaffinity="0" group="4" />
    <geom name="world_ee_path_80" type="sphere" pos="0.0355022471823 0.0368977758084 0.660726581529" size="0.006" rgba="1 0.58 0.05 0.9" contype="0" conaffinity="0" group="4" />
    <geom name="world_ee_path_81" type="sphere" pos="0.0340686560453 0.0290107135614 0.662262234047" size="0.006" rgba="1 0.58 0.05 0.9" contype="0" conaffinity="0" group="4" />
    <geom name="world_ee_path_82" type="sphere" pos="0.0325456549184 0.0215519766221 0.663199348778" size="0.006" rgba="1 0.58 0.05 0.9" contype="0" conaffinity="0" group="4" />
    <geom name="world_ee_path_83" type="sphere" pos="0.031188103323 0.0147274481471 0.663511056728" size="0.006" rgba="1 0.58 0.05 0.9" contype="0" conaffinity="0" group="4" />
  </worldbody>
</mujoco>